Workbook

Sheet Cell Info
A1: Customer: | B1: GM
A2: End User: | B2: GM
A3: Plant (Abbreviate): | B3: ORN
A4: Job #: | B4: 9628-003
A5: Station #: | B5: ZJ040
A6: Function: | B6: NFP 3 FRONT PIERCE
A7: Model: | B7: T1XXF1_2 | N7: Delete unused info from "PRNT" tabs
A10: Output (do not modify): | B10: =CONCATENATE(B2," ", B3, " - ", B5, " - ", B6, " - ", B7) -> GM ORN - ZJ040 - NFP 3 FRONT PIERCE - T1XXF1_2
A14: Notes:
A15: - Be sure that all info on "PRNT" tabs are justified LEFT and CENTER. This simplifies label printing for the MFG team.
A16: - If cell info on "PRNT" tabs is not being used, delete it. This includes label QTY as well as "0" (zeros). Again, this helps MFG.
A17: - Only modify cells shaded in Yellow. All other cells have formulas driven by yellow shaded cells.
A18: -This label file also functions as an example. When ready to use, please use the macro buttons to clear out yellow cells.
A21: You MUST save as a .xlsx file type. The label printer does not recognize a macro-enabled Excel file

Sheet Device Cables
A1: Job Number | B1: ='Cell Info'!B4 -> 9628-003 | K1: Job Number | L1: =B1 -> 9628-003
A2: Job Desc: | B2: ='Cell Info'!B10 -> GM ORN - ZJ040 - NFP 3 FRONT PIERCE - T1XXF1_2 | K2: Job Desc: | L2: =B2 -> GM ORN - ZJ040 - NFP 3 FRONT PIERCE - T1XXF1_2
A4: Robot / FRAME | B4: From Device | C4: To Device | D4: Cable Part # | E4: TYPE | F4: SYNC BOX PORT | G4: Type | H4: LABEL | I4: QTY | K4: Robot / FRAME | L4: From Device | M4: To Device | N4: Cable Part # | O4: TYPE | P4: LABEL | Q4: QTY | T4: Device Labels
A5: R05 | B5: CB05-1 | C5: SR05-5 | D5: 3100-0136-02 | E5: POWER | F5: 1 | G5: =VLOOKUP(MID(C5,1,2),LOOKUP!$A:$B,2,FALSE)&MID(C5,FIND("-",C5)+1,3) -> IS5 | H5: =IF(E5="POWER","PWR","1G")&"-SP"&F5&"-"&G5 -> PWR-SP1-IS5 | I5: 2 | K5: =A5 -> R05 | L5: =B5 -> CB05-1 | M5: =C5 -> SR05-5 | N5: =D5 -> 3100-0136-02 | O5: =E5 -> POWER | P5: =H5 -> PWR-SP1-IS5 | Q5: =I5 -> 2 | T5: =IF(C5=0, "",C5) -> SR05-5
A6: =A5 -> R05 | B6: =B5 -> CB05-1 | C6: =C5 -> SR05-5 | D6: ="3100-0229-"&MID(D5,11,2) -> 3100-0229-02 | E6: ETHERNET | F6: =F5 -> 1 | G6: =VLOOKUP(MID(C6,1,2),LOOKUP!$A:$B,2,FALSE)&MID(C6,FIND("-",C6)+1,3) -> IS5 | H6: =IF(E6="POWER","PWR","1G")&"-SP"&F6&"-"&G6 -> 1G-SP1-IS5 | I6: 2 | K6: =A6 -> R05 | L6: =B6 -> CB05-1 | M6: =C6 -> SR05-5 | N6: =D6 -> 3100-0229-02 | O6: =E6 -> ETHERNET | P6: =H6 -> 1G-SP1-IS5 | Q6: =I6 -> 2 | T6: =IF(C6=0, "",C6) -> SR05-5
A7: R05 | B7: CB05-1 | C7: NT05-1 | D7: 3100-0244-02 | E7: POWER | F7: 2 | G7: =VLOOKUP(MID(C7,1,2),LOOKUP!$A:$B,2,FALSE)&MID(C7,FIND("-",C7)+1,3) -> NT1 | H7: =IF(E7="POWER","PWR","1G")&"-SP"&F7&"-"&G7 -> PWR-SP2-NT1 | I7: 2 | K7: =A7 -> R05 | L7: =B7 -> CB05-1 | M7: =C7 -> NT05-1 | N7: =D7 -> 3100-0244-02 | O7: =E7 -> POWER | P7: =H7 -> PWR-SP2-NT1 | Q7: =I7 -> 2 | T7: =IF(C7=0, "",C7) -> NT05-1
A8: =A7 -> R05 | B8: =B7 -> CB05-1 | C8: =C7 -> NT05-1 | D8: ="3100-0233-"&MID(D7,11,2) -> 3100-0233-02 | E8: ETHERNET | F8: =F7 -> 2 | G8: =VLOOKUP(MID(C8,1,2),LOOKUP!$A:$B,2,FALSE)&MID(C8,FIND("-",C8)+1,3) -> NT1 | H8: =IF(E8="POWER","PWR","1G")&"-SP"&F8&"-"&G8 -> 1G-SP2-NT1 | I8: 2 | K8: =A8 -> R05 | L8: =B8 -> CB05-1 | M8: =C8 -> NT05-1 | N8: =D8 -> 3100-0233-02 | O8: =E8 -> ETHERNET | P8: =H8 -> 1G-SP2-NT1 | Q8: =I8 -> 2 | T8: =IF(C8=0, "",C8) -> NT05-1
A9: R05 | B9: CB05-1 | C9: NT05-2 | D9: 3100-0244-02 | E9: POWER | F9: 3 | G9: =VLOOKUP(MID(C9,1,2),LOOKUP!$A:$B,2,FALSE)&MID(C9,FIND("-",C9)+1,3) -> NT2 | H9: =IF(E9="POWER","PWR","1G")&"-SP"&F9&"-"&G9 -> PWR-SP3-NT2 | I9: 2 | K9: =A9 -> R05 | L9: =B9 -> CB05-1 | M9: =C9 -> NT05-2 | N9: =D9 -> 3100-0244-02 | O9: =E9 -> POWER | P9: =H9 -> PWR-SP3-NT2 | Q9: =I9 -> 2 | T9: =IF(C9=0, "",C9) -> NT05-2
A10: =A9 -> R05 | B10: =B9 -> CB05-1 | C10: =C9 -> NT05-2 | D10: ="3100-0233-"&MID(D9,11,2) -> 3100-0233-02 | E10: ETHERNET | F10: =F9 -> 3 | G10: =VLOOKUP(MID(C10,1,2),LOOKUP!$A:$B,2,FALSE)&MID(C10,FIND("-",C10)+1,3) -> NT2 | H10: =IF(E10="POWER","PWR","1G")&"-SP"&F10&"-"&G10 -> 1G-SP3-NT2 | I10: 2 | K10: =A10 -> R05 | L10: =B10 -> CB05-1 | M10: =C10 -> NT05-2 | N10: =D10 -> 3100-0233-02 | O10: =E10 -> ETHERNET | P10: =H10 -> 1G-SP3-NT2 | Q10: =I10 -> 2 | T10: =IF(C10=0, "",C10) -> NT05-2
A11: R06 | B11: CB06-1 | C11: SR06-6 | D11: 3100-0136-02 | E11: POWER | F11: 1 | G11: =VLOOKUP(MID(C11,1,2),LOOKUP!$A:$B,2,FALSE)&MID(C11,FIND("-",C11)+1,3) -> IS6 | H11: =IF(E11="POWER","PWR","1G")&"-SP"&F11&"-"&G11 -> PWR-SP1-IS6 | I11: 2 | K11: =A11 -> R06 | L11: =B11 -> CB06-1 | M11: =C11 -> SR06-6 | N11: =D11 -> 3100-0136-02 | O11: =E11 -> POWER | P11: =H11 -> PWR-SP1-IS6 | Q11: =I11 -> 2 | T11: =IF(C11=0, "",C11) -> SR06-6
A12: =A11 -> R06 | B12: =B11 -> CB06-1 | C12: =C11 -> SR06-6 | D12: ="3100-0229-"&MID(D11,11,2) -> 3100-0229-02 | E12: ETHERNET | F12: =F11 -> 1 | G12: =VLOOKUP(MID(C12,1,2),LOOKUP!$A:$B,2,FALSE)&MID(C12,FIND("-",C12)+1,3) -> IS6 | H12: =IF(E12="POWER","PWR","1G")&"-SP"&F12&"-"&G12 -> 1G-SP1-IS6 | I12: 2 | K12: =A12 -> R06 | L12: =B12 -> CB06-1 | M12: =C12 -> SR06-6 | N12: =D12 -> 3100-0229-02 | O12: =E12 -> ETHERNET | P12: =H12 -> 1G-SP1-IS6 | Q12: =I12 -> 2 | T12: =IF(C12=0, "",C12) -> SR06-6
A13: R06 | B13: CB06-1 | C13: NT06-1 | D13: 3100-0244-02 | E13: POWER | F13: 2 | G13: =VLOOKUP(MID(C13,1,2),LOOKUP!$A:$B,2,FALSE)&MID(C13,FIND("-",C13)+1,3) -> NT1 | H13: =IF(E13="POWER","PWR","1G")&"-SP"&F13&"-"&G13 -> PWR-SP2-NT1 | I13: 2 | K13: =A13 -> R06 | L13: =B13 -> CB06-1 | M13: =C13 -> NT06-1 | N13: =D13 -> 3100-0244-02 | O13: =E13 -> POWER | P13: =H13 -> PWR-SP2-NT1 | Q13: =I13 -> 2 | T13: =IF(C13=0, "",C13) -> NT06-1
A14: =A13 -> R06 | B14: =B13 -> CB06-1 | C14: =C13 -> NT06-1 | D14: ="3100-0233-"&MID(D13,11,2) -> 3100-0233-02 | E14: ETHERNET | F14: =F13 -> 2 | G14: =VLOOKUP(MID(C14,1,2),LOOKUP!$A:$B,2,FALSE)&MID(C14,FIND("-",C14)+1,3) -> NT1 | H14: =IF(E14="POWER","PWR","1G")&"-SP"&F14&"-"&G14 -> 1G-SP2-NT1 | I14: 2 | K14: =A14 -> R06 | L14: =B14 -> CB06-1 | M14: =C14 -> NT06-1 | N14: =D14 -> 3100-0233-02 | O14: =E14 -> ETHERNET | P14: =H14 -> 1G-SP2-NT1 | Q14: =I14 -> 2 | T14: =IF(C14=0, "",C14) -> NT06-1
A15: R06 | B15: CB06-1 | C15: NT06-2 | D15: 3100-0244-02 | E15: POWER | F15: 3 | G15: =VLOOKUP(MID(C15,1,2),LOOKUP!$A:$B,2,FALSE)&MID(C15,FIND("-",C15)+1,3) -> NT2 | H15: =IF(E15="POWER","PWR","1G")&"-SP"&F15&"-"&G15 -> PWR-SP3-NT2 | I15: 2 | K15: =A15 -> R06 | L15: =B15 -> CB06-1 | M15: =C15 -> NT06-2 | N15: =D15 -> 3100-0244-02 | O15: =E15 -> POWER | P15: =H15 -> PWR-SP3-NT2 | Q15: =I15 -> 2 | T15: =IF(C15=0, "",C15) -> NT06-2
A16: =A15 -> R06 | B16: =B15 -> CB06-1 | C16: =C15 -> NT06-2 | D16: ="3100-0233-"&MID(D15,11,2) -> 3100-0233-02 | E16: ETHERNET | F16: =F15 -> 3 | G16: =VLOOKUP(MID(C16,1,2),LOOKUP!$A:$B,2,FALSE)&MID(C16,FIND("-",C16)+1,3) -> NT2 | H16: =IF(E16="POWER","PWR","1G")&"-SP"&F16&"-"&G16 -> 1G-SP3-NT2 | I16: 2 | K16: =A16 -> R06 | L16: =B16 -> CB06-1 | M16: =C16 -> NT06-2 | N16: =D16 -> 3100-0233-02 | O16: =E16 -> ETHERNET | P16: =H16 -> 1G-SP3-NT2 | Q16: =I16 -> 2 | T16: =IF(C16=0, "",C16) -> NT06-2
A17: LFFLR-V | B17: CB-3 | C17: SF-1 | D17: 3100-0372-05 | E17: POWER | F17: 1 | G17: =VLOOKUP(MID(C17,1,2),LOOKUP!$A:$B,2,FALSE)&MID(C17,FIND("-",C17)+1,3) -> IS1 | H17: =IF(E17="POWER","PWR","1G")&"-SP"&F17&"-"&G17 -> PWR-SP1-IS1 | I17: 2 | K17: =A17 -> LFFLR-V | L17: =B17 -> CB-3 | M17: =C17 -> SF-1 | N17: =D17 -> 3100-0372-05 | O17: =E17 -> POWER | P17: =H17 -> PWR-SP1-IS1 | Q17: =I17 -> 2 | T17: =IF(C17=0, "",C17) -> SF-1
A18: =A17 -> LFFLR-V | B18: =B17 -> CB-3 | C18: =C17 -> SF-1 | D18: ="3100-0229-"&MID(D17,11,2) -> 3100-0229-05 | E18: ETHERNET | F18: =F17 -> 1 | G18: =VLOOKUP(MID(C18,1,2),LOOKUP!$A:$B,2,FALSE)&MID(C18,FIND("-",C18)+1,3) -> IS1 | H18: =IF(E18="POWER","PWR","1G")&"-SP"&F18&"-"&G18 -> 1G-SP1-IS1 | I18: 2 | K18: =A18 -> LFFLR-V | L18: =B18 -> CB-3 | M18: =C18 -> SF-1 | N18: =D18 -> 3100-0229-05 | O18: =E18 -> ETHERNET | P18: =H18 -> 1G-SP1-IS1 | Q18: =I18 -> 2 | T18: =IF(C18=0, "",C18) -> SF-1
A19: LFFLR-V | B19: CB-3 | C19: SF-3 | D19: 3100-0372-05 | E19: POWER | F19: 2 | G19: =VLOOKUP(MID(C19,1,2),LOOKUP!$A:$B,2,FALSE)&MID(C19,FIND("-",C19)+1,3) -> IS3 | H19: =IF(E19="POWER","PWR","1G")&"-SP"&F19&"-"&G19 -> PWR-SP2-IS3 | I19: 2 | K19: =A19 -> LFFLR-V | L19: =B19 -> CB-3 | M19: =C19 -> SF-3 | N19: =D19 -> 3100-0372-05 | O19: =E19 -> POWER | P19: =H19 -> PWR-SP2-IS3 | Q19: =I19 -> 2 | T19: =IF(C19=0, "",C19) -> SF-3
A20: =A19 -> LFFLR-V | B20: =B19 -> CB-3 | C20: =C19 -> SF-3 | D20: ="3100-0229-"&MID(D19,11,2) -> 3100-0229-05 | E20: ETHERNET | F20: =F19 -> 2 | G20: =VLOOKUP(MID(C20,1,2),LOOKUP!$A:$B,2,FALSE)&MID(C20,FIND("-",C20)+1,3) -> IS3 | H20: =IF(E20="POWER","PWR","1G")&"-SP"&F20&"-"&G20 -> 1G-SP2-IS3 | I20: 2 | K20: =A20 -> LFFLR-V | L20: =B20 -> CB-3 | M20: =C20 -> SF-3 | N20: =D20 -> 3100-0229-05 | O20: =E20 -> ETHERNET | P20: =H20 -> 1G-SP2-IS3 | Q20: =I20 -> 2 | T20: =IF(C20=0, "",C20) -> SF-3
A21: LFFLR-V | B21: CB-3 | C21: SLA-1 | D21: 3100-0372-05 | E21: POWER | F21: 3 | G21: =VLOOKUP(MID(C21,1,2),LOOKUP!$A:$B,2,FALSE)&MID(C21,FIND("-",C21)+1,3) -> SLA1 | H21: =IF(E21="POWER","PWR","1G")&"-SP"&F21&"-"&G21 -> PWR-SP3-SLA1 | I21: 2 | K21: =A21 -> LFFLR-V | L21: =B21 -> CB-3 | M21: =C21 -> SLA-1 | N21: =D21 -> 3100-0372-05 | O21: =E21 -> POWER | P21: =H21 -> PWR-SP3-SLA1 | Q21: =I21 -> 2 | T21: =IF(C21=0, "",C21) -> SLA-1
A22: =A21 -> LFFLR-V | B22: =B21 -> CB-3 | C22: =C21 -> SLA-1 | D22: ="3100-0233-"&MID(D21,11,2) -> 3100-0233-05 | E22: ETHERNET | F22: =F21 -> 3 | G22: =VLOOKUP(MID(C22,1,2),LOOKUP!$A:$B,2,FALSE)&MID(C22,FIND("-",C22)+1,3) -> SLA1 | H22: =IF(E22="POWER","PWR","1G")&"-SP"&F22&"-"&G22 -> 1G-SP3-SLA1 | I22: 2 | K22: =A22 -> LFFLR-V | L22: =B22 -> CB-3 | M22: =C22 -> SLA-1 | N22: =D22 -> 3100-0233-05 | O22: =E22 -> ETHERNET | P22: =H22 -> 1G-SP3-SLA1 | Q22: =I22 -> 2 | T22: =IF(C22=0, "",C22) -> SLA-1
A23: LFFLR-V | B23: CB-3 | C23: SLA-3 | D23: 3100-0372-05 | E23: POWER | F23: 4 | G23: =VLOOKUP(MID(C23,1,2),LOOKUP!$A:$B,2,FALSE)&MID(C23,FIND("-",C23)+1,3) -> SLA3 | H23: =IF(E23="POWER","PWR","1G")&"-SP"&F23&"-"&G23 -> PWR-SP4-SLA3 | I23: 2 | K23: =A23 -> LFFLR-V | L23: =B23 -> CB-3 | M23: =C23 -> SLA-3 | N23: =D23 -> 3100-0372-05 | O23: =E23 -> POWER | P23: =H23 -> PWR-SP4-SLA3 | Q23: =I23 -> 2 | T23: =IF(C23=0, "",C23) -> SLA-3
A24: =A23 -> LFFLR-V | B24: =B23 -> CB-3 | C24: =C23 -> SLA-3 | D24: ="3100-0233-"&MID(D23,11,2) -> 3100-0233-05 | E24: ETHERNET | F24: =F23 -> 4 | G24: =VLOOKUP(MID(C24,1,2),LOOKUP!$A:$B,2,FALSE)&MID(C24,FIND("-",C24)+1,3) -> SLA3 | H24: =IF(E24="POWER","PWR","1G")&"-SP"&F24&"-"&G24 -> 1G-SP4-SLA3 | I24: 2 | K24: =A24 -> LFFLR-V | L24: =B24 -> CB-3 | M24: =C24 -> SLA-3 | N24: =D24 -> 3100-0233-05 | O24: =E24 -> ETHERNET | P24: =H24 -> 1G-SP4-SLA3 | Q24: =I24 -> 2 | T24: =IF(C24=0, "",C24) -> SLA-3
A25: RHFLR-V | B25: CB-4 | C25: SF-2 | D25: 3100-0372-05 | E25: POWER | F25: 1 | G25: =VLOOKUP(MID(C25,1,2),LOOKUP!$A:$B,2,FALSE)&MID(C25,FIND("-",C25)+1,3) -> IS2 | H25: =IF(E25="POWER","PWR","1G")&"-SP"&F25&"-"&G25 -> PWR-SP1-IS2 | I25: 2 | K25: =A25 -> RHFLR-V | L25: =B25 -> CB-4 | M25: =C25 -> SF-2 | N25: =D25 -> 3100-0372-05 | O25: =E25 -> POWER | P25: =H25 -> PWR-SP1-IS2 | Q25: =I25 -> 2 | T25: =IF(C25=0, "",C25) -> SF-2
A26: =A25 -> RHFLR-V | B26: =B25 -> CB-4 | C26: =C25 -> SF-2 | D26: ="3100-0229-"&MID(D25,11,2) -> 3100-0229-05 | E26: ETHERNET | F26: =F25 -> 1 | G26: =VLOOKUP(MID(C26,1,2),LOOKUP!$A:$B,2,FALSE)&MID(C26,FIND("-",C26)+1,3) -> IS2 | H26: =IF(E26="POWER","PWR","1G")&"-SP"&F26&"-"&G26 -> 1G-SP1-IS2 | I26: 2 | K26: =A26 -> RHFLR-V | L26: =B26 -> CB-4 | M26: =C26 -> SF-2 | N26: =D26 -> 3100-0229-05 | O26: =E26 -> ETHERNET | P26: =H26 -> 1G-SP1-IS2 | Q26: =I26 -> 2 | T26: =IF(C26=0, "",C26) -> SF-2
A27: RHFLR-V | B27: CB-4 | C27: SF-4 | D27: 3100-0372-05 | E27: POWER | F27: 2 | G27: =VLOOKUP(MID(C27,1,2),LOOKUP!$A:$B,2,FALSE)&MID(C27,FIND("-",C27)+1,3) -> IS4 | H27: =IF(E27="POWER","PWR","1G")&"-SP"&F27&"-"&G27 -> PWR-SP2-IS4 | I27: 2 | K27: =A27 -> RHFLR-V | L27: =B27 -> CB-4 | M27: =C27 -> SF-4 | N27: =D27 -> 3100-0372-05 | O27: =E27 -> POWER | P27: =H27 -> PWR-SP2-IS4 | Q27: =I27 -> 2 | T27: =IF(C27=0, "",C27) -> SF-4
A28: =A27 -> RHFLR-V | B28: =B27 -> CB-4 | C28: =C27 -> SF-4 | D28: ="3100-0229-"&MID(D27,11,2) -> 3100-0229-05 | E28: ETHERNET | F28: =F27 -> 2 | G28: =VLOOKUP(MID(C28,1,2),LOOKUP!$A:$B,2,FALSE)&MID(C28,FIND("-",C28)+1,3) -> IS4 | H28: =IF(E28="POWER","PWR","1G")&"-SP"&F28&"-"&G28 -> 1G-SP2-IS4 | I28: 2 | K28: =A28 -> RHFLR-V | L28: =B28 -> CB-4 | M28: =C28 -> SF-4 | N28: =D28 -> 3100-0229-05 | O28: =E28 -> ETHERNET | P28: =H28 -> 1G-SP2-IS4 | Q28: =I28 -> 2 | T28: =IF(C28=0, "",C28) -> SF-4
A29: RHFLR-V | B29: CB-4 | C29: SLA-2 | D29: 3100-0372-05 | E29: POWER | F29: 3 | G29: =VLOOKUP(MID(C29,1,2),LOOKUP!$A:$B,2,FALSE)&MID(C29,FIND("-",C29)+1,3) -> SLA2 | H29: =IF(E29="POWER","PWR","1G")&"-SP"&F29&"-"&G29 -> PWR-SP3-SLA2 | I29: 2 | K29: =A29 -> RHFLR-V | L29: =B29 -> CB-4 | M29: =C29 -> SLA-2 | N29: =D29 -> 3100-0372-05 | O29: =E29 -> POWER | P29: =H29 -> PWR-SP3-SLA2 | Q29: =I29 -> 2 | T29: =IF(C29=0, "",C29) -> SLA-2
A30: =A29 -> RHFLR-V | B30: =B29 -> CB-4 | C30: =C29 -> SLA-2 | D30: ="3100-0233-"&MID(D29,11,2) -> 3100-0233-05 | E30: ETHERNET | F30: =F29 -> 3 | G30: =VLOOKUP(MID(C30,1,2),LOOKUP!$A:$B,2,FALSE)&MID(C30,FIND("-",C30)+1,3) -> SLA2 | H30: =IF(E30="POWER","PWR","1G")&"-SP"&F30&"-"&G30 -> 1G-SP3-SLA2 | I30: 2 | K30: =A30 -> RHFLR-V | L30: =B30 -> CB-4 | M30: =C30 -> SLA-2 | N30: =D30 -> 3100-0233-05 | O30: =E30 -> ETHERNET | P30: =H30 -> 1G-SP3-SLA2 | Q30: =I30 -> 2 | T30: =IF(C30=0, "",C30) -> SLA-2
A31: RHFLR-V | B31: CB-4 | C31: SLA-4 | D31: 3100-0372-05 | E31: POWER | F31: 4 | G31: =VLOOKUP(MID(C31,1,2),LOOKUP!$A:$B,2,FALSE)&MID(C31,FIND("-",C31)+1,3) -> SLA4 | H31: =IF(E31="POWER","PWR","1G")&"-SP"&F31&"-"&G31 -> PWR-SP4-SLA4 | I31: 2 | K31: =A31 -> RHFLR-V | L31: =B31 -> CB-4 | M31: =C31 -> SLA-4 | N31: =D31 -> 3100-0372-05 | O31: =E31 -> POWER | P31: =H31 -> PWR-SP4-SLA4 | Q31: =I31 -> 2 | T31: =IF(C31=0, "",C31) -> SLA-4
A32: =A31 -> RHFLR-V | B32: =B31 -> CB-4 | C32: =C31 -> SLA-4 | D32: ="3100-0233-"&MID(D31,11,2) -> 3100-0233-05 | E32: ETHERNET | F32: =F31 -> 4 | G32: =VLOOKUP(MID(C32,1,2),LOOKUP!$A:$B,2,FALSE)&MID(C32,FIND("-",C32)+1,3) -> SLA4 | H32: =IF(E32="POWER","PWR","1G")&"-SP"&F32&"-"&G32 -> 1G-SP4-SLA4 | I32: 2 | K32: =A32 -> RHFLR-V | L32: =B32 -> CB-4 | M32: =C32 -> SLA-4 | N32: =D32 -> 3100-0233-05 | O32: =E32 -> ETHERNET | P32: =H32 -> 1G-SP4-SLA4 | Q32: =I32 -> 2 | T32: =IF(C32=0, "",C32) -> SLA-4
A33: MET-V | B33: CB-1 | C33: MS-1 | D33: 3100-0372-10 | E33: POWER | F33: 1 | G33: =VLOOKUP(MID(C33,1,2),LOOKUP!$A:$B,2,FALSE)&MID(C33,FIND("-",C33)+1,3) -> MS1 | H33: =IF(E33="POWER","PWR","1G")&"-SP"&F33&"-"&G33 -> PWR-SP1-MS1 | I33: 2 | K33: =A33 -> MET-V | L33: =B33 -> CB-1 | M33: =C33 -> MS-1 | N33: =D33 -> 3100-0372-10 | O33: =E33 -> POWER | P33: =H33 -> PWR-SP1-MS1 | Q33: =I33 -> 2 | T33: =IF(C33=0, "",C33) -> MS-1
A34: =A33 -> MET-V | B34: =B33 -> CB-1 | C34: =C33 -> MS-1 | D34: ="3100-0233-"&MID(D33,11,2) -> 3100-0233-10 | E34: ETHERNET | F34: =F33 -> 1 | G34: =VLOOKUP(MID(C34,1,2),LOOKUP!$A:$B,2,FALSE)&MID(C34,FIND("-",C34)+1,3) -> MS1 | H34: =IF(E34="POWER","PWR","1G")&"-SP"&F34&"-"&G34 -> 1G-SP1-MS1 | I34: 2 | K34: =A34 -> MET-V | L34: =B34 -> CB-1 | M34: =C34 -> MS-1 | N34: =D34 -> 3100-0233-10 | O34: =E34 -> ETHERNET | P34: =H34 -> 1G-SP1-MS1 | Q34: =I34 -> 2 | T34: =IF(C34=0, "",C34) -> MS-1
A35: MET-V | B35: CB-1 | C35: MS-4 | D35: 3100-0372-15 | E35: POWER | F35: 2 | G35: =VLOOKUP(MID(C35,1,2),LOOKUP!$A:$B,2,FALSE)&MID(C35,FIND("-",C35)+1,3) -> MS4 | H35: =IF(E35="POWER","PWR","1G")&"-SP"&F35&"-"&G35 -> PWR-SP2-MS4 | I35: 2 | K35: =A35 -> MET-V | L35: =B35 -> CB-1 | M35: =C35 -> MS-4 | N35: =D35 -> 3100-0372-15 | O35: =E35 -> POWER | P35: =H35 -> PWR-SP2-MS4 | Q35: =I35 -> 2 | T35: =IF(C35=0, "",C35) -> MS-4
A36: =A35 -> MET-V | B36: =B35 -> CB-1 | C36: =C35 -> MS-4 | D36: ="3100-0233-"&MID(D35,11,2) -> 3100-0233-15 | E36: ETHERNET | F36: =F35 -> 2 | G36: =VLOOKUP(MID(C36,1,2),LOOKUP!$A:$B,2,FALSE)&MID(C36,FIND("-",C36)+1,3) -> MS4 | H36: =IF(E36="POWER","PWR","1G")&"-SP"&F36&"-"&G36 -> 1G-SP2-MS4 | I36: 2 | K36: =A36 -> MET-V | L36: =B36 -> CB-1 | M36: =C36 -> MS-4 | N36: =D36 -> 3100-0233-15 | O36: =E36 -> ETHERNET | P36: =H36 -> 1G-SP2-MS4 | Q36: =I36 -> 2 | T36: =IF(C36=0, "",C36) -> MS-4
A37: MET-V | B37: CB-1 | C37: MS-5 | D37: 3100-0372-10 | E37: POWER | F37: 3 | G37: =VLOOKUP(MID(C37,1,2),LOOKUP!$A:$B,2,FALSE)&MID(C37,FIND("-",C37)+1,3) -> MS5 | H37: =IF(E37="POWER","PWR","1G")&"-SP"&F37&"-"&G37 -> PWR-SP3-MS5 | I37: 2 | K37: =A37 -> MET-V | L37: =B37 -> CB-1 | M37: =C37 -> MS-5 | N37: =D37 -> 3100-0372-10 | O37: =E37 -> POWER | P37: =H37 -> PWR-SP3-MS5 | Q37: =I37 -> 2 | T37: =IF(C37=0, "",C37) -> MS-5
A38: =A37 -> MET-V | B38: =B37 -> CB-1 | C38: =C37 -> MS-5 | D38: ="3100-0233-"&MID(D37,11,2) -> 3100-0233-10 | E38: ETHERNET | F38: =F37 -> 3 | G38: =VLOOKUP(MID(C38,1,2),LOOKUP!$A:$B,2,FALSE)&MID(C38,FIND("-",C38)+1,3) -> MS5 | H38: =IF(E38="POWER","PWR","1G")&"-SP"&F38&"-"&G38 -> 1G-SP3-MS5 | I38: 2 | K38: =A38 -> MET-V | L38: =B38 -> CB-1 | M38: =C38 -> MS-5 | N38: =D38 -> 3100-0233-10 | O38: =E38 -> ETHERNET | P38: =H38 -> 1G-SP3-MS5 | Q38: =I38 -> 2 | T38: =IF(C38=0, "",C38) -> MS-5
A39: MET-V | B39: CB-2 | C39: MS-2 | D39: 3100-0372-10 | E39: POWER | F39: 1 | G39: =VLOOKUP(MID(C39,1,2),LOOKUP!$A:$B,2,FALSE)&MID(C39,FIND("-",C39)+1,3) -> MS2 | H39: =IF(E39="POWER","PWR","1G")&"-SP"&F39&"-"&G39 -> PWR-SP1-MS2 | I39: 2 | K39: =A39 -> MET-V | L39: =B39 -> CB-2 | M39: =C39 -> MS-2 | N39: =D39 -> 3100-0372-10 | O39: =E39 -> POWER | P39: =H39 -> PWR-SP1-MS2 | Q39: =I39 -> 2 | T39: =IF(C39=0, "",C39) -> MS-2
A40: =A39 -> MET-V | B40: =B39 -> CB-2 | C40: =C39 -> MS-2 | D40: ="3100-0233-"&MID(D39,11,2) -> 3100-0233-10 | E40: ETHERNET | F40: =F39 -> 1 | G40: =VLOOKUP(MID(C40,1,2),LOOKUP!$A:$B,2,FALSE)&MID(C40,FIND("-",C40)+1,3) -> MS2 | H40: =IF(E40="POWER","PWR","1G")&"-SP"&F40&"-"&G40 -> 1G-SP1-MS2 | I40: 2 | K40: =A40 -> MET-V | L40: =B40 -> CB-2 | M40: =C40 -> MS-2 | N40: =D40 -> 3100-0233-10 | O40: =E40 -> ETHERNET | P40: =H40 -> 1G-SP1-MS2 | Q40: =I40 -> 2 | T40: =IF(C40=0, "",C40) -> MS-2
A41: MET-V | B41: CB-2 | C41: MS-3 | D41: 3100-0372-15 | E41: POWER | F41: 2 | G41: =VLOOKUP(MID(C41,1,2),LOOKUP!$A:$B,2,FALSE)&MID(C41,FIND("-",C41)+1,3) -> MS3 | H41: =IF(E41="POWER","PWR","1G")&"-SP"&F41&"-"&G41 -> PWR-SP2-MS3 | I41: 2 | K41: =A41 -> MET-V | L41: =B41 -> CB-2 | M41: =C41 -> MS-3 | N41: =D41 -> 3100-0372-15 | O41: =E41 -> POWER | P41: =H41 -> PWR-SP2-MS3 | Q41: =I41 -> 2 | T41: =IF(C41=0, "",C41) -> MS-3
...

Sheet PRNT Device Cables
A1: Device | B1: Qty
A2: =IF('Device Cables'!H5<>"",'Device Cables'!H5,"") -> PWR-SP1-IS5 | B2: =IF('Device Cables'!I5<>"",'Device Cables'!I5,"") -> 2
A3: =IF('Device Cables'!H6<>"",'Device Cables'!H6,"") -> 1G-SP1-IS5 | B3: =IF('Device Cables'!I6<>"",'Device Cables'!I6,"") -> 2
A4: =IF('Device Cables'!H7<>"",'Device Cables'!H7,"") -> PWR-SP2-NT1 | B4: =IF('Device Cables'!I7<>"",'Device Cables'!I7,"") -> 2
A5: =IF('Device Cables'!H8<>"",'Device Cables'!H8,"") -> 1G-SP2-NT1 | B5: =IF('Device Cables'!I8<>"",'Device Cables'!I8,"") -> 2
A6: =IF('Device Cables'!H9<>"",'Device Cables'!H9,"") -> PWR-SP3-NT2 | B6: =IF('Device Cables'!I9<>"",'Device Cables'!I9,"") -> 2
A7: =IF('Device Cables'!H10<>"",'Device Cables'!H10,"") -> 1G-SP3-NT2 | B7: =IF('Device Cables'!I10<>"",'Device Cables'!I10,"") -> 2
A8: =IF('Device Cables'!H11<>"",'Device Cables'!H11,"") -> PWR-SP1-IS6 | B8: =IF('Device Cables'!I11<>"",'Device Cables'!I11,"") -> 2
A9: =IF('Device Cables'!H12<>"",'Device Cables'!H12,"") -> 1G-SP1-IS6 | B9: =IF('Device Cables'!I12<>"",'Device Cables'!I12,"") -> 2
A10: =IF('Device Cables'!H13<>"",'Device Cables'!H13,"") -> PWR-SP2-NT1 | B10: =IF('Device Cables'!I13<>"",'Device Cables'!I13,"") -> 2
A11: =IF('Device Cables'!H14<>"",'Device Cables'!H14,"") -> 1G-SP2-NT1 | B11: =IF('Device Cables'!I14<>"",'Device Cables'!I14,"") -> 2
A12: =IF('Device Cables'!H15<>"",'Device Cables'!H15,"") -> PWR-SP3-NT2 | B12: =IF('Device Cables'!I15<>"",'Device Cables'!I15,"") -> 2
A13: =IF('Device Cables'!H16<>"",'Device Cables'!H16,"") -> 1G-SP3-NT2 | B13: =IF('Device Cables'!I16<>"",'Device Cables'!I16,"") -> 2
... A657: =IF('Device Cables'!H660<>"",'Device Cables'!H660,"") | B657: =IF('Device Cables'!I660<>"",'Device Cables'!I660,"")

Sheet PRNT Device Labels
A1: Line 1 | B1: Qty
A2: {=_xlfn.UNIQUE(_xlfn._xlws.FILTER('Device Cables'!T5:T48,'Device Cables'!T5:T48<>""))} -> SR05-5 | B2: =IF(A2<>"",5,"") -> 5
A3: NT05-1 | B3: =IF(A3<>"",5,"") -> 5
A4: NT05-2 | B4: =IF(A4<>"",5,"") -> 5
A5: SR06-6 | B5: =IF(A5<>"",5,"") -> 5
A6: NT06-1 | B6: =IF(A6<>"",5,"") -> 5
A7: NT06-2 | B7: =IF(A7<>"",5,"") -> 5
A8: SF-1 | B8: =IF(A8<>"",5,"") -> 5
A9: SF-3 | B9: =IF(A9<>"",5,"") -> 5
A10: SLA-1 | B10: =IF(A10<>"",5,"") -> 5
A11: SLA-3 | B11: =IF(A11<>"",5,"") -> 5
A12: SF-2 | B12: =IF(A12<>"",5,"") -> 5
A13: SF-4 | B13: =IF(A13<>"",5,"") -> 5
A14: SLA-2 | B14: =IF(A14<>"",5,"") -> 5
... A21: MS-6 | B21: =IF(A21<>"",5,"") -> 5
B22: =IF(A22<>"",5,"")
B23: =IF(A23<>"",5,"")
B24: =IF(A24<>"",5,"")
B25: =IF(A25<>"",5,"")
B26: =IF(A26<>"",5,"")
B27: =IF(A27<>"",5,"")
B28: =IF(A28<>"",5,"")
B29: =IF(A29<>"",5,"")
B30: =IF(A30<>"",5,"")
B31: =IF(A31<>"",5,"")
B32: =IF(A32<>"",5,"")
B33: =IF(A33<>"",5,"")
... B43: =IF(A43<>"",5,"")

Sheet Artifact Labels
A1: INPUT ARTIFACT NUMBERS HERE | B1: Add "AF" / "AR" Prefix | C1: Output to PRNT
A2: 05-1 | B2: ="AR"&A2 -> AR05-1 | C2: =IF(A2<>"",B2," ") -> AR05-1 | E2: *NOTE: to prevent Excel from confusing a " - " with a function, put a " ' " (apostrophe) before the artifact name
A3: 06-1 | B3: ="AR"&A3 -> AR06-1 | C3: =IF(A3<>"",B3," ") -> AR06-1 | E3: Ex. Instead of 01-1, type '01-1
A4: SR05-1 | B4: ="AF"&A4 -> AFSR05-1 | C4: =IF(A4<>"",B4," ") -> AFSR05-1 | E4: Feel free to change "AF" (Fixed Artifact) to "AR" (Robot Mounted Artifact) under "Add AF/AR Prefix" column as needed
A5: SR06-1 | B5: ="AF"&A5 -> AFSR06-1 | C5: =IF(A5<>"",B5," ") -> AFSR06-1
B6: ="AF"&A6 -> AF | C6: =IF(A6<>"",B6," ")
B7: ="AF"&A7 -> AF | C7: =IF(A7<>"",B7," ")
B8: ="AF"&A8 -> AF | C8: =IF(A8<>"",B8," ")
B9: ="AF"&A9 -> AF | C9: =IF(A9<>"",B9," ")
B10: ="AF"&A10 -> AF | C10: =IF(A10<>"",B10," ")
B11: ="AF"&A11 -> AF | C11: =IF(A11<>"",B11," ")
B12: ="AF"&A12 -> AF | C12: =IF(A12<>"",B12," ")
B13: ="AF"&A13 -> AF | C13: =IF(A13<>"",B13," ")
B14: ="AF"&A14 -> AF | C14: =IF(A14<>"",B14," ")
B15: ="AF"&A15 -> AF | C15: =IF(A15<>"",B15," ")
B16: ="AF"&A16 -> AF | C16: =IF(A16<>"",B16," ")

Sheet PRNT Artifact Labels
A1: Line 1 | B1: Qty
A2: =IF('Artifact Labels'!C2=0, " ",'Artifact Labels'!C2) -> AR05-1 | B2: =IF(A2<>" ",3," ") -> 3
A3: =IF('Artifact Labels'!C3=0, " ",'Artifact Labels'!C3) -> AR06-1 | B3: =IF(A3<>" ",3," ") -> 3
A4: =IF('Artifact Labels'!C4=0, " ",'Artifact Labels'!C4) -> AFSR05-1 | B4: =IF(A4<>" ",3," ") -> 3
A5: =IF('Artifact Labels'!C5=0, " ",'Artifact Labels'!C5) -> AFSR06-1 | B5: =IF(A5<>" ",3," ") -> 3
A6: =IF('Artifact Labels'!C6=0, " ",'Artifact Labels'!C6) | B6: =IF(A6<>" ",3," ")
A7: =IF('Artifact Labels'!C7=0, " ",'Artifact Labels'!C7) | B7: =IF(A7<>" ",3," ")
A8: =IF('Artifact Labels'!C8=0, " ",'Artifact Labels'!C8) | B8: =IF(A8<>" ",3," ")
A9: =IF('Artifact Labels'!C9=0, " ",'Artifact Labels'!C9) | B9: =IF(A9<>" ",3," ")
A10: =IF('Artifact Labels'!C10=0, " ",'Artifact Labels'!C10) | B10: =IF(A10<>" ",3," ")
A11: =IF('Artifact Labels'!C11=0, " ",'Artifact Labels'!C11) | B11: =IF(A11<>" ",3," ")
A12: =IF('Artifact Labels'!C12=0, " ",'Artifact Labels'!C12) | B12: =IF(A12<>" ",3," ")
A13: =IF('Artifact Labels'!C13=0, " ",'Artifact Labels'!C13) | B13: =IF(A13<>" ",3," ")
... A15: =IF('Artifact Labels'!C15=0, " ",'Artifact Labels'!C15) | B15: =IF(A15<>" ",3," ")

Sheet Air Handler & Pedestal Labels
A1: INPUT AH/PED NUMBERS HERE | B1: Add Correct Prefix | C1: Output to PRNT
B2: ="PED"&-A2 -> PED0 | C2: =IF(A2<>"",B2," ") | E2: *NOTE: to prevent Excel from confusing a " - " with a function, put a " ' " (apostrophe) before the artifact name
B3: ="PED"&-A3 -> PED0 | C3: =IF(A3<>"",B3," ") | E3: Ex. Instead of 01-1, type '01-1
B4: ="PED"&-A4 -> PED0 | C4: =IF(A4<>"",B4," ")
B5: ="PED"&-A5 -> PED0 | C5: =IF(A5<>"",B5," ")
B6: ="PED"&-A6 -> PED0 | C6: =IF(A6<>"",B6," ")
B7: ="PED"&-A7 -> PED0 | C7: =IF(A7<>"",B7," ")
B8: ="PED"&-A8 -> PED0 | C8: =IF(A8<>"",B8," ")
B9: ="PED"&-A9 -> PED0 | C9: =IF(A9<>"",B9," ")
B10: ="AH"&-A10 -> AH0 | C10: =IF(A10<>"",B10," ")
B11: ="AH"&-A11 -> AH0 | C11: =IF(A11<>"",B11," ")
B12: ="AH"&-A12 -> AH0 | C12: =IF(A12<>"",B12," ")
B13: ="AH"&-A13 -> AH0 | C13: =IF(A13<>"",B13," ")
B14: ="AH"&-A14 -> AH0 | C14: =IF(A14<>"",B14," ")
B15: ="AH"&-A15 -> AH0 | C15: =IF(A15<>"",B15," ")
B16: ="AH"&-A16 -> AH0 | C16: =IF(A16<>"",B16," ")
B17: ="AH"&-A17 -> AH0 | C17: =IF(A17<>"",B17," ")

Sheet PRNT AH & PED Labels
A1: Line 1 | B1: Qty
A2: =IF('Air Handler & Pedestal Labels'!C2=0, " ",'Air Handler & Pedestal Labels'!C2) | B2: =IF(A2<>" ",3," ")
A3: =IF('Air Handler & Pedestal Labels'!C3=0, " ",'Air Handler & Pedestal Labels'!C3) | B3: =IF(A3<>" ",3," ")
A4: =IF('Air Handler & Pedestal Labels'!C4=0, " ",'Air Handler & Pedestal Labels'!C4) | B4: =IF(A4<>" ",3," ")
A5: =IF('Air Handler & Pedestal Labels'!C5=0, " ",'Air Handler & Pedestal Labels'!C5) | B5: =IF(A5<>" ",3," ")
A6: =IF('Air Handler & Pedestal Labels'!C6=0, " ",'Air Handler & Pedestal Labels'!C6) | B6: =IF(A6<>" ",3," ")
A7: =IF('Air Handler & Pedestal Labels'!C7=0, " ",'Air Handler & Pedestal Labels'!C7) | B7: =IF(A7<>" ",3," ")
A8: =IF('Air Handler & Pedestal Labels'!C8=0, " ",'Air Handler & Pedestal Labels'!C8) | B8: =IF(A8<>" ",3," ")
A9: =IF('Air Handler & Pedestal Labels'!C9=0, " ",'Air Handler & Pedestal Labels'!C9) | B9: =IF(A9<>" ",3," ")
A10: =IF('Air Handler & Pedestal Labels'!C10=0, " ",'Air Handler & Pedestal Labels'!C10) | B10: =IF(A10<>" ",3," ")
A11: =IF('Air Handler & Pedestal Labels'!C11=0, " ",'Air Handler & Pedestal Labels'!C11) | B11: =IF(A11<>" ",3," ")
A12: =IF('Air Handler & Pedestal Labels'!C12=0, " ",'Air Handler & Pedestal Labels'!C12) | B12: =IF(A12<>" ",3," ")
A13: =IF('Air Handler & Pedestal Labels'!C13=0, " ",'Air Handler & Pedestal Labels'!C13) | B13: =IF(A13<>" ",3," ")
... A18: =IF('Air Handler & Pedestal Labels'!C18=0, " ",'Air Handler & Pedestal Labels'!C18) | B18: =IF(A18<>" ",3," ")

Sheet ENC to Device Cables
A1: Job Number | B1: ='Device Cables'!B1 -> 9628-003 | L1: Job Number | M1: =B1 -> 9628-003
A2: Job Desc: | B2: ='Device Cables'!B2 -> GM ORN - ZJ040 - NFP 3 FRONT PIERCE - T1XXF1_2 | L2: Job Desc: | M2: =B2 -> GM ORN - ZJ040 - NFP 3 FRONT PIERCE - T1XXF1_2
A4: Device | B4: FROM | C4: TO | D4: Cable Part # | E4: TYPE | F4: Device | G4: C-1 | H4: C-2 | I4: QTY | L4: Device | M4: FROM | N4: TO | O4: Cable Part # | P4: TYPE | Q4: Device | R4: TYPE | S4: END | T4: End Gender | W4: CB/SB/RM Labels
A5: CB05-1 | B5: ENC | C5: J1 | D5: 3100-0234-30 | E5: POWER | F5: =A5 -> CB05-1 | G5: =E5 -> POWER | H5: =B5 -> ENC | I5: 1 | L5: =A5 -> CB05-1 | M5: =B5 -> ENC | N5: =C5 -> J1 | O5: =D5 -> 3100-0234-30 | P5: =E5 -> POWER | Q5: =F5 -> CB05-1 | R5: =G5 -> POWER | S5: =H5 -> ENC | T5: MALE | W5: =IF(A5=0, "",A5) -> CB05-1
F6: =A5 -> CB05-1 | G6: =E5 -> POWER | H6: =C5 -> J1 | I6: 1 | Q6: =F6 -> CB05-1 | R6: =G6 -> POWER | S6: =H6 -> J1 | T6: FEMALE | W6: =IF(A6=0, "",A6)
D7: ="3100-0231-"&MID(D5,11,2) -> 3100-0231-30 | E7: ETHERNET | F7: =A5 -> CB05-1 | G7: =E7 -> ETHERNET | H7: =B5 -> ENC | I7: 1 | O7: =D7 -> 3100-0231-30 | P7: =E7 -> ETHERNET | Q7: =F7 -> CB05-1 | R7: =G7 -> ETHERNET | S7: =H7 -> ENC | T7: MALE | W7: =IF(A7=0, "",A7)
D8: ="3100-0233-"&MID(D7,11,2) -> 3100-0233-30 | F8: =A5 -> CB05-1 | G8: =E7 -> ETHERNET | H8: =C5 -> J1 | I8: 1 | Q8: =F8 -> CB05-1 | R8: =G8 -> ETHERNET | S8: =H8 -> J1 | T8: FEMALE | W8: =IF(A8=0, "",A8)
B9: J1 | C9: J3 | D9: 3100-0234-10 | E9: POWER | F9: =A5 -> CB05-1 | G9: =E9 -> POWER | H9: =B9 -> J1 | I9: 1 | M9: =B9 -> J1 | N9: =C9 -> J3 | O9: =D9 -> 3100-0234-10 | P9: =E9 -> POWER | Q9: =F9 -> CB05-1 | R9: =G9 -> POWER | S9: =H9 -> J1 | T9: MALE | W9: =IF(A9=0, "",A9)
F10: =A5 -> CB05-1 | G10: =E9 -> POWER | H10: =C9 -> J3 | I10: 1 | Q10: =F10 -> CB05-1 | R10: =G10 -> POWER | S10: =H10 -> J3 | T10: FEMALE | W10: =IF(A10=0, "",A10)
D11: ="3100-0232-"&MID(D9,11,2) -> 3100-0232-10 | E11: ETHERNET | F11: =A5 -> CB05-1 | G11: =E11 -> ETHERNET | H11: =B9 -> J1 | I11: 1 | O11: =D11 -> 3100-0232-10 | P11: =E11 -> ETHERNET | Q11: =F11 -> CB05-1 | R11: =G11 -> ETHERNET | S11: =H11 -> J1 | T11: MALE | W11: =IF(A11=0, "",A11)
D12: ="3100-0233-"&MID(D11,11,2) -> 3100-0233-10 | F12: =A5 -> CB05-1 | G12: =E11 -> ETHERNET | H12: =C9 -> J3 | I12: 1 | Q12: =F12 -> CB05-1 | R12: =G12 -> ETHERNET | S12: =H12 -> J3 | T12: FEMALE | W12: =IF(A12=0, "",A12)
B13: J3 | C13: =A5 -> CB05-1 | D13: 3100-0234-07 | E13: POWER | F13: =A5 -> CB05-1 | G13: =E13 -> POWER | H13: =B13 -> J3 | I13: 1 | M13: =B13 -> J3 | N13: =C13 -> CB05-1 | O13: =D13 -> 3100-0234-07 | P13: =E13 -> POWER | Q13: =F13 -> CB05-1 | R13: =G13 -> POWER | S13: =H13 -> J3 | T13: MALE | W13: =IF(A13=0, "",A13)
F14: =A5 -> CB05-1 | G14: =E13 -> POWER | H14: =C13 -> CB05-1 | I14: 1 | Q14: =F14 -> CB05-1 | R14: =G14 -> POWER | S14: =H14 -> CB05-1 | T14: FEMALE | W14: =IF(A14=0, "",A14)
D15: ="3100-0233-"&MID(D13,11,2) -> 3100-0233-07 | E15: ETHERNET | F15: =A5 -> CB05-1 | G15: =E15 -> ETHERNET | H15: =B13 -> J3 | I15: 1 | O15: =D15 -> 3100-0233-07 | P15: =E15 -> ETHERNET | Q15: =F15 -> CB05-1 | R15: =G15 -> ETHERNET | S15: =H15 -> J3 | T15: MALE | W15: =IF(A15=0, "",A15)
D16: ="3100-0233-"&MID(D15,11,2) -> 3100-0233-07 | F16: =A5 -> CB05-1 | G16: =E15 -> ETHERNET | H16: =C13 -> CB05-1 | I16: 1 | Q16: =F16 -> CB05-1 | R16: =G16 -> ETHERNET | S16: =H16 -> CB05-1 | T16: MALE | W16: =IF(A16=0, "",A16)
A17: CB06-1 | B17: ENC | C17: J1 | D17: 3100-0234-15 | E17: POWER | F17: =A17 -> CB06-1 | G17: =E17 -> POWER | H17: =B17 -> ENC | I17: 1 | L17: =A17 -> CB06-1 | M17: =B17 -> ENC | N17: =C17 -> J1 | O17: =D17 -> 3100-0234-15 | P17: =E17 -> POWER | Q17: =F17 -> CB06-1 | R17: =G17 -> POWER | S17: =H17 -> ENC | T17: MALE | W17: =IF(A17=0, "",A17) -> CB06-1
F18: =A17 -> CB06-1 | G18: =E17 -> POWER | H18: =C17 -> J1 | I18: 1 | Q18: =F18 -> CB06-1 | R18: =G18 -> POWER | S18: =H18 -> J1 | T18: FEMALE | W18: =IF(A18=0, "",A18)
D19: ="3100-0231-"&MID(D17,11,2) -> 3100-0231-15 | E19: ETHERNET | F19: =A17 -> CB06-1 | G19: =E19 -> ETHERNET | H19: =B17 -> ENC | I19: 1 | O19: =D19 -> 3100-0231-15 | P19: =E19 -> ETHERNET | Q19: =F19 -> CB06-1 | R19: =G19 -> ETHERNET | S19: =H19 -> ENC | T19: MALE | W19: =IF(A19=0, "",A19)
D20: ="3100-0233-"&MID(D19,11,2) -> 3100-0233-15 | F20: =A17 -> CB06-1 | G20: =E19 -> ETHERNET | H20: =C17 -> J1 | I20: 1 | Q20: =F20 -> CB06-1 | R20: =G20 -> ETHERNET | S20: =H20 -> J1 | T20: FEMALE | W20: =IF(A20=0, "",A20)
B21: J1 | C21: J3 | D21: 3100-0234-10 | E21: POWER | F21: =A17 -> CB06-1 | G21: =E21 -> POWER | H21: =B21 -> J1 | I21: 1 | M21: =B21 -> J1 | N21: =C21 -> J3 | O21: =D21 -> 3100-0234-10 | P21: =E21 -> POWER | Q21: =F21 -> CB06-1 | R21: =G21 -> POWER | S21: =H21 -> J1 | T21: MALE | W21: =IF(A21=0, "",A21)
F22: =A17 -> CB06-1 | G22: =E21 -> POWER | H22: =C21 -> J3 | I22: 1 | Q22: =F22 -> CB06-1 | R22: =G22 -> POWER | S22: =H22 -> J3 | T22: FEMALE | W22: =IF(A22=0, "",A22)
D23: ="3100-0232-"&MID(D21,11,2) -> 3100-0232-10 | E23: ETHERNET | F23: =A17 -> CB06-1 | G23: =E23 -> ETHERNET | H23: =B21 -> J1 | I23: 1 | O23: =D23 -> 3100-0232-10 | P23: =E23 -> ETHERNET | Q23: =F23 -> CB06-1 | R23: =G23 -> ETHERNET | S23: =H23 -> J1 | T23: MALE | W23: =IF(A23=0, "",A23)
D24: ="3100-0233-"&MID(D23,11,2) -> 3100-0233-10 | F24: =A17 -> CB06-1 | G24: =E23 -> ETHERNET | H24: =C21 -> J3 | I24: 1 | Q24: =F24 -> CB06-1 | R24: =G24 -> ETHERNET | S24: =H24 -> J3 | T24: FEMALE | W24: =IF(A24=0, "",A24)
B25: J3 | C25: =A17 -> CB06-1 | D25: 3100-0234-07 | E25: POWER | F25: =A17 -> CB06-1 | G25: =E25 -> POWER | H25: =B25 -> J3 | I25: 1 | M25: =B25 -> J3 | N25: =C25 -> CB06-1 | O25: =D25 -> 3100-0234-07 | P25: =E25 -> POWER | Q25: =F25 -> CB06-1 | R25: =G25 -> POWER | S25: =H25 -> J3 | T25: MALE | W25: =IF(A25=0, "",A25)
F26: =A17 -> CB06-1 | G26: =E25 -> POWER | H26: =C25 -> CB06-1 | I26: 1 | Q26: =F26 -> CB06-1 | R26: =G26 -> POWER | S26: =H26 -> CB06-1 | T26: FEMALE | W26: =IF(A26=0, "",A26)
D27: ="3100-0233-"&MID(D25,11,2) -> 3100-0233-07 | E27: ETHERNET | F27: =A17 -> CB06-1 | G27: =E27 -> ETHERNET | H27: =B25 -> J3 | I27: 1 | O27: =D27 -> 3100-0233-07 | P27: =E27 -> ETHERNET | Q27: =F27 -> CB06-1 | R27: =G27 -> ETHERNET | S27: =H27 -> J3 | T27: MALE | W27: =IF(A27=0, "",A27)
D28: ="3100-0233-"&MID(D27,11,2) -> 3100-0233-07 | F28: =A17 -> CB06-1 | G28: =E27 -> ETHERNET | H28: =C25 -> CB06-1 | I28: 1 | Q28: =F28 -> CB06-1 | R28: =G28 -> ETHERNET | S28: =H28 -> CB06-1 | T28: MALE | W28: =IF(A28=0, "",A28)
A29: CB-3 | B29: ENC | C29: =A29 -> CB-3 | D29: 3100-0234-35 | E29: POWER | F29: =A29 -> CB-3 | G29: =E29 -> POWER | H29: =B29 -> ENC | I29: 1 | L29: =A29 -> CB-3 | M29: =B29 -> ENC | N29: =C29 -> CB-3 | O29: =D29 -> 3100-0234-35 | P29: =E29 -> POWER | Q29: =F29 -> CB-3 | R29: =G29 -> POWER | S29: =H29 -> ENC | T29: MALE | W29: =IF(A29=0, "",A29) -> CB-3
F30: =A29 -> CB-3 | G30: =E29 -> POWER | H30: =C29 -> CB-3 | I30: 1 | Q30: =F30 -> CB-3 | R30: =G30 -> POWER | S30: =H30 -> CB-3 | T30: FEMALE | W30: =IF(A30=0, "",A30)
D31: ="3100-0233-"&MID(D29,11,2) -> 3100-0233-35 | E31: ETHERNET | F31: =A29 -> CB-3 | G31: =E31 -> ETHERNET | H31: =B29 -> ENC | I31: 1 | O31: =D31 -> 3100-0233-35 | P31: =E31 -> ETHERNET | Q31: =F31 -> CB-3 | R31: =G31 -> ETHERNET | S31: =H31 -> ENC | T31: MALE | W31: =IF(A31=0, "",A31)
D32: ="3100-0233-"&MID(D31,11,2) -> 3100-0233-35 | F32: =A29 -> CB-3 | G32: =E31 -> ETHERNET | H32: =C29 -> CB-3 | I32: 1 | Q32: =F32 -> CB-3 | R32: =G32 -> ETHERNET | S32: =H32 -> CB-3 | T32: MALE | W32: =IF(A32=0, "",A32)
A33: CB-4 | B33: ENC | C33: =A33 -> CB-4 | D33: 3100-0234-25 | E33: POWER | F33: =A33 -> CB-4 | G33: =E33 -> POWER | H33: =B33 -> ENC | I33: 1 | L33: =A33 -> CB-4 | M33: =B33 -> ENC | N33: =C33 -> CB-4 | O33: =D33 -> 3100-0234-25 | P33: =E33 -> POWER | Q33: =F33 -> CB-4 | R33: =G33 -> POWER | S33: =H33 -> ENC | T33: MALE | W33: =IF(A33=0, "",A33) -> CB-4
F34: =A33 -> CB-4 | G34: =E33 -> POWER | H34: =C33 -> CB-4 | I34: 1 | Q34: =F34 -> CB-4 | R34: =G34 -> POWER | S34: =H34 -> CB-4 | T34: FEMALE | W34: =IF(A34=0, "",A34)
D35: ="3100-0233-"&MID(D33,11,2) -> 3100-0233-25 | E35: ETHERNET | F35: =A33 -> CB-4 | G35: =E35 -> ETHERNET | H35: =B33 -> ENC | I35: 1 | O35: =D35 -> 3100-0233-25 | P35: =E35 -> ETHERNET | Q35: =F35 -> CB-4 | R35: =G35 -> ETHERNET | S35: =H35 -> ENC | T35: MALE | W35: =IF(A35=0, "",A35)
D36: ="3100-0233-"&MID(D35,11,2) -> 3100-0233-25 | F36: =A33 -> CB-4 | G36: =E35 -> ETHERNET | H36: =C33 -> CB-4 | I36: 1 | Q36: =F36 -> CB-4 | R36: =G36 -> ETHERNET | S36: =H36 -> CB-4 | T36: MALE | W36: =IF(A36=0, "",A36)
A37: CB-1 | B37: ENC | C37: =A37 -> CB-1 | D37: 3100-0234-35 | E37: POWER | F37: =A37 -> CB-1 | G37: =E37 -> POWER | H37: =B37 -> ENC | I37: 1 | L37: =A37 -> CB-1 | M37: =B37 -> ENC | N37: =C37 -> CB-1 | O37: =D37 -> 3100-0234-35 | P37: =E37 -> POWER | Q37: =F37 -> CB-1 | R37: =G37 -> POWER | S37: =H37 -> ENC | T37: MALE | W37: =IF(A37=0, "",A37) -> CB-1
F38: =A37 -> CB-1 | G38: =E37 -> POWER | H38: =C37 -> CB-1 | I38: 1 | Q38: =F38 -> CB-1 | R38: =G38 -> POWER | S38: =H38 -> CB-1 | T38: FEMALE | W38: =IF(A38=0, "",A38)
D39: ="3100-0233-"&MID(D37,11,2) -> 3100-0233-35 | E39: ETHERNET | F39: =A37 -> CB-1 | G39: =E39 -> ETHERNET | H39: =B37 -> ENC | I39: 1 | O39: =D39 -> 3100-0233-35 | P39: =E39 -> ETHERNET | Q39: =F39 -> CB-1 | R39: =G39 -> ETHERNET | S39: =H39 -> ENC | T39: MALE | W39: =IF(A39=0, "",A39)
D40: ="3100-0233-"&MID(D39,11,2) -> 3100-0233-35 | F40: =A37 -> CB-1 | G40: =E39 -> ETHERNET | H40: =C37 -> CB-1 | I40: 1 | Q40: =F40 -> CB-1 | R40: =G40 -> ETHERNET | S40: =H40 -> CB-1 | T40: MALE | W40: =IF(A40=0, "",A40)
A41: CB-2 | B41: ENC | C41: =A41 -> CB-2 | D41: 3100-0234-25 | E41: POWER | F41: =A41 -> CB-2 | G41: =E41 -> POWER | H41: =B41 -> ENC | I41: 1 | L41: =A41 -> CB-2 | M41: =B41 -> ENC | N41: =C41 -> CB-2 | O41: =D41 -> 3100-0234-25 | P41: =E41 -> POWER | Q41: =F41 -> CB-2 | R41: =G41 -> POWER | S41: =H41 -> ENC | T41: MALE | W41: =IF(A41=0, "",A41) -> CB-2
...

Sheet PRNT ENC Cables
A1: Device | B1: C-1 | C1: C-2 | D1: Qty
A2: =IF('ENC to Device Cables'!F5<>"",'ENC to Device Cables'!F5,"") -> CB05-1 | B2: =IF(A2<>"",'ENC to Device Cables'!G5,"") -> POWER | C2: =IF(A2<>"",'ENC to Device Cables'!H5,"") -> ENC | D2: =IF(A2<>"",'ENC to Device Cables'!I5,"") -> 1
A3: =IF('ENC to Device Cables'!F6<>"",'ENC to Device Cables'!F6,"") -> CB05-1 | B3: =IF(A3<>"",'ENC to Device Cables'!G6,"") -> POWER | C3: =IF(A3<>"",'ENC to Device Cables'!H6,"") -> J1 | D3: =IF(A3<>"",'ENC to Device Cables'!I6,"") -> 1
A4: =IF('ENC to Device Cables'!F7<>"",'ENC to Device Cables'!F7,"") -> CB05-1 | B4: =IF(A4<>"",'ENC to Device Cables'!G7,"") -> ETHERNET | C4: =IF(A4<>"",'ENC to Device Cables'!H7,"") -> ENC | D4: =IF(A4<>"",'ENC to Device Cables'!I7,"") -> 1
A5: =IF('ENC to Device Cables'!F8<>"",'ENC to Device Cables'!F8,"") -> CB05-1 | B5: =IF(A5<>"",'ENC to Device Cables'!G8,"") -> ETHERNET | C5: =IF(A5<>"",'ENC to Device Cables'!H8,"") -> J1 | D5: =IF(A5<>"",'ENC to Device Cables'!I8,"") -> 1
A6: =IF('ENC to Device Cables'!F9<>"",'ENC to Device Cables'!F9,"") -> CB05-1 | B6: =IF(A6<>"",'ENC to Device Cables'!G9,"") -> POWER | C6: =IF(A6<>"",'ENC to Device Cables'!H9,"") -> J1 | D6: =IF(A6<>"",'ENC to Device Cables'!I9,"") -> 1
A7: =IF('ENC to Device Cables'!F10<>"",'ENC to Device Cables'!F10,"") -> CB05-1 | B7: =IF(A7<>"",'ENC to Device Cables'!G10,"") -> POWER | C7: =IF(A7<>"",'ENC to Device Cables'!H10,"") -> J3 | D7: =IF(A7<>"",'ENC to Device Cables'!I10,"") -> 1
A8: =IF('ENC to Device Cables'!F11<>"",'ENC to Device Cables'!F11,"") -> CB05-1 | B8: =IF(A8<>"",'ENC to Device Cables'!G11,"") -> ETHERNET | C8: =IF(A8<>"",'ENC to Device Cables'!H11,"") -> J1 | D8: =IF(A8<>"",'ENC to Device Cables'!I11,"") -> 1
A9: =IF('ENC to Device Cables'!F12<>"",'ENC to Device Cables'!F12,"") -> CB05-1 | B9: =IF(A9<>"",'ENC to Device Cables'!G12,"") -> ETHERNET | C9: =IF(A9<>"",'ENC to Device Cables'!H12,"") -> J3 | D9: =IF(A9<>"",'ENC to Device Cables'!I12,"") -> 1
A10: =IF('ENC to Device Cables'!F13<>"",'ENC to Device Cables'!F13,"") -> CB05-1 | B10: =IF(A10<>"",'ENC to Device Cables'!G13,"") -> POWER | C10: =IF(A10<>"",'ENC to Device Cables'!H13,"") -> J3 | D10: =IF(A10<>"",'ENC to Device Cables'!I13,"") -> 1
A11: =IF('ENC to Device Cables'!F14<>"",'ENC to Device Cables'!F14,"") -> CB05-1 | B11: =IF(A11<>"",'ENC to Device Cables'!G14,"") -> POWER | C11: =IF(A11<>"",'ENC to Device Cables'!H14,"") -> CB05-1 | D11: =IF(A11<>"",'ENC to Device Cables'!I14,"") -> 1
A12: =IF('ENC to Device Cables'!F15<>"",'ENC to Device Cables'!F15,"") -> CB05-1 | B12: =IF(A12<>"",'ENC to Device Cables'!G15,"") -> ETHERNET | C12: =IF(A12<>"",'ENC to Device Cables'!H15,"") -> J3 | D12: =IF(A12<>"",'ENC to Device Cables'!I15,"") -> 1
A13: =IF('ENC to Device Cables'!F16<>"",'ENC to Device Cables'!F16,"") -> CB05-1 | B13: =IF(A13<>"",'ENC to Device Cables'!G16,"") -> ETHERNET | C13: =IF(A13<>"",'ENC to Device Cables'!H16,"") -> CB05-1 | D13: =IF(A13<>"",'ENC to Device Cables'!I16,"") -> 1
... A58: =IF('ENC to Device Cables'!F61<>"",'ENC to Device Cables'!F61,"") | B58: =IF(A58<>"",'ENC to Device Cables'!G61,"") | C58: =IF(A58<>"",'ENC to Device Cables'!H61,"") | D58: =IF(A58<>"",'ENC to Device Cables'!I61,"")
A59: =IF('ENC to Device Cables'!F138<>"",'ENC to Device Cables'!F138,"") | B59: =IF(A59<>"",'ENC to Device Cables'!G138,"") | C59: =IF(A59<>"",'ENC to Device Cables'!H138,"") | D59: =IF(A59<>"",'ENC to Device Cables'!I138,"")
A60: =IF('ENC to Device Cables'!F139<>"",'ENC to Device Cables'!F139,"") | B60: =IF(A60<>"",'ENC to Device Cables'!G139,"") | C60: =IF(A60<>"",'ENC to Device Cables'!H139,"") | D60: =IF(A60<>"",'ENC to Device Cables'!I139,"")
A61: =IF('ENC to Device Cables'!F140<>"",'ENC to Device Cables'!F140,"") | B61: =IF(A61<>"",'ENC to Device Cables'!G140,"") | C61: =IF(A61<>"",'ENC to Device Cables'!H140,"") | D61: =IF(A61<>"",'ENC to Device Cables'!I140,"")
A62: =IF('ENC to Device Cables'!F141<>"",'ENC to Device Cables'!F141,"") | B62: =IF(A62<>"",'ENC to Device Cables'!G141,"") | C62: =IF(A62<>"",'ENC to Device Cables'!H141,"") | D62: =IF(A62<>"",'ENC to Device Cables'!I141,"")
A63: =IF('ENC to Device Cables'!F142<>"",'ENC to Device Cables'!F142,"") | B63: =IF(A63<>"",'ENC to Device Cables'!G142,"") | C63: =IF(A63<>"",'ENC to Device Cables'!H142,"") | D63: =IF(A63<>"",'ENC to Device Cables'!I142,"")
A64: =IF('ENC to Device Cables'!F143<>"",'ENC to Device Cables'!F143,"") | B64: =IF(A64<>"",'ENC to Device Cables'!G143,"") | C64: =IF(A64<>"",'ENC to Device Cables'!H143,"") | D64: =IF(A64<>"",'ENC to Device Cables'!I143,"")
A65: =IF('ENC to Device Cables'!F144<>"",'ENC to Device Cables'!F144,"") | B65: =IF(A65<>"",'ENC to Device Cables'!G144,"") | C65: =IF(A65<>"",'ENC to Device Cables'!H144,"") | D65: =IF(A65<>"",'ENC to Device Cables'!I144,"")
A66: =IF('ENC to Device Cables'!F145<>"",'ENC to Device Cables'!F145,"") | B66: =IF(A66<>"",'ENC to Device Cables'!G145,"") | C66: =IF(A66<>"",'ENC to Device Cables'!H145,"") | D66: =IF(A66<>"",'ENC to Device Cables'!I145,"")
A67: =IF('ENC to Device Cables'!F146<>"",'ENC to Device Cables'!F146,"") | B67: =IF(A67<>"",'ENC to Device Cables'!G146,"") | C67: =IF(A67<>"",'ENC to Device Cables'!H146,"") | D67: =IF(A67<>"",'ENC to Device Cables'!I146,"")
A68: =IF('ENC to Device Cables'!F147<>"",'ENC to Device Cables'!F147,"") | B68: =IF(A68<>"",'ENC to Device Cables'!G147,"") | C68: =IF(A68<>"",'ENC to Device Cables'!H147,"") | D68: =IF(A68<>"",'ENC to Device Cables'!I147,"")
A69: =IF('ENC to Device Cables'!F148<>"",'ENC to Device Cables'!F148,"") | B69: =IF(A69<>"",'ENC to Device Cables'!G148,"") | C69: =IF(A69<>"",'ENC to Device Cables'!H148,"") | D69: =IF(A69<>"",'ENC to Device Cables'!I148,"")
A70: =IF('ENC to Device Cables'!F149<>"",'ENC to Device Cables'!F149,"") | B70: =IF(A70<>"",'ENC to Device Cables'!G149,"") | C70: =IF(A70<>"",'ENC to Device Cables'!H149,"") | D70: =IF(A70<>"",'ENC to Device Cables'!I149,"")
... A777: =IF('ENC to Device Cables'!F856<>"",'ENC to Device Cables'!F856,"") | B777: =IF(A777<>"",'ENC to Device Cables'!G856,"") | C777: =IF(A777<>"",'ENC to Device Cables'!H856,"") | D777: =IF(A777<>"",'ENC to Device Cables'!I856,"")

Sheet PRNT ENC Devices
A1: Device | B1: Qty
A2: {=_xlfn.UNIQUE(_xlfn._xlws.FILTER('ENC to Device Cables'!W5:W152,'ENC to Device Cables'!W5:W152<>""))} -> CB05-1 | B2: =IF(A2<>"",5,"") -> 5
A3: CB06-1 | B3: =IF(A3<>"",5,"") -> 5
A4: CB-3 | B4: =IF(A4<>"",5,"") -> 5
A5: CB-4 | B5: =IF(A5<>"",5,"") -> 5
A6: CB-1 | B6: =IF(A6<>"",5,"") -> 5
A7: CB-2 | B7: =IF(A7<>"",5,"") -> 5
A8: RM-1 | B8: =IF(A8<>"",5,"") -> 5
A9: RM-2 | B9: =IF(A9<>"",5,"") -> 5
A10: PD-2 | B10: =IF(A10<>"",5,"") -> 5
B11: =IF(A11<>"",5,"")
B12: =IF(A12<>"",5,"")
B13: =IF(A13<>"",5,"")
B14: =IF(A14<>"",5,"")
B15: =IF(A15<>"",5,"")
B16: =IF(A16<>"",5,"")
B17: =IF(A17<>"",5,"")
B18: =IF(A18<>"",5,"")
B19: =IF(A19<>"",5,"")
B20: =IF(A20<>"",5,"")
B21: =IF(A21<>"",5,"")
B22: =IF(A22<>"",5,"")
... B36: =IF(A36<>"",5,"")

Sheet ENC Labels
H1: D12 | I1: =MID(H1,1,1)&MID(H1,2,2)+2 -> D14 | J1: =MID(I1,1,1)&MID(I1,2,2)+2 -> D16 | K1: =MID(J1,1,1)&MID(J1,2,2)+2 -> D18 | L1: =MID(K1,1,1)&MID(K1,2,2)+2 -> D20 | M1: =MID(L1,1,1)&MID(L1,2,2)+2 -> D22 | N1: =MID(M1,1,1)&MID(M1,2,2)+2 -> D24 | O1: =MID(N1,1,1)&MID(N1,2,2)+2 -> D26 | P1: =MID(O1,1,1)&MID(O1,2,2)+2 -> D28 | ... V1: =MID(U1,1,1)&MID(U1,2,2)+2 -> D40 | W1: =MID(V1,1,1)&MID(V1,2,2)+1 -> D41 | X1: =MID(W1,1,1)&MID(W1,2,2)+1 -> D42 | Y1: =MID(X1,1,1)&MID(X1,2,2)+1 -> D43 | AB1: PORT LAYOUT
H2: E12 | I2: =MID(H2,1,1)&MID(H2,2,2)+2 -> E14 | J2: =MID(I2,1,1)&MID(I2,2,2)+2 -> E16 | K2: =MID(J2,1,1)&MID(J2,2,2)+2 -> E18 | L2: =MID(K2,1,1)&MID(K2,2,2)+2 -> E20 | M2: =MID(L2,1,1)&MID(L2,2,2)+2 -> E22 | N2: =MID(M2,1,1)&MID(M2,2,2)+2 -> E24 | O2: =MID(N2,1,1)&MID(N2,2,2)+2 -> E26 | P2: =MID(O2,1,1)&MID(O2,2,2)+2 -> E28 | ... V2: =MID(U2,1,1)&MID(U2,2,2)+2 -> E40 | W2: =MID(V2,1,1)&MID(V2,2,2)+1 -> E41 | X2: =MID(W2,1,1)&MID(W2,2,2)+1 -> E42 | Y2: =MID(X2,1,1)&MID(X2,2,2)+1 -> E43 | AB2: SIDE OF ENCLOSURE
H3: F12 | I3: =MID(H3,1,1)&MID(H3,2,2)+2 -> F14 | J3: =MID(I3,1,1)&MID(I3,2,2)+2 -> F16 | K3: =MID(J3,1,1)&MID(J3,2,2)+2 -> F18 | L3: =MID(K3,1,1)&MID(K3,2,2)+2 -> F20 | M3: =MID(L3,1,1)&MID(L3,2,2)+2 -> F22 | N3: =MID(M3,1,1)&MID(M3,2,2)+2 -> F24 | O3: =MID(N3,1,1)&MID(N3,2,2)+2 -> F26 | P3: =MID(O3,1,1)&MID(O3,2,2)+2 -> F28 | ... V3: =MID(U3,1,1)&MID(U3,2,2)+2 -> F40 | W3: =MID(V3,1,1)&MID(V3,2,2)+1 -> F41 | X3: =MID(W3,1,1)&MID(W3,2,2)+1 -> F42 | Y3: =MID(X3,1,1)&MID(X3,2,2)+1 -> F43
H4: D13 | I4: =MID(H4,1,1)&MID(H4,2,2)+2 -> D15 | J4: =MID(I4,1,1)&MID(I4,2,2)+2 -> D17 | K4: =MID(J4,1,1)&MID(J4,2,2)+2 -> D19 | L4: =MID(K4,1,1)&MID(K4,2,2)+2 -> D21 | M4: =MID(L4,1,1)&MID(L4,2,2)+2 -> D23 | N4: =MID(M4,1,1)&MID(M4,2,2)+2 -> D25 | O4: =MID(N4,1,1)&MID(N4,2,2)+2 -> D27 | P4: =MID(O4,1,1)&MID(O4,2,2)+2 -> D29 | ... V4: =MID(U4,1,1)&MID(U4,2,2)+2 -> D41 | W4: =MID(V4,1,1)&MID(V4,2,2)+1 -> D42 | X4: =MID(W4,1,1)&MID(W4,2,2)+1 -> D43 | Y4: =MID(X4,1,1)&MID(X4,2,2)+1 -> D44
H5: E13 | I5: =MID(H5,1,1)&MID(H5,2,2)+2 -> E15 | J5: =MID(I5,1,1)&MID(I5,2,2)+2 -> E17 | K5: =MID(J5,1,1)&MID(J5,2,2)+2 -> E19 | L5: =MID(K5,1,1)&MID(K5,2,2)+2 -> E21 | M5: =MID(L5,1,1)&MID(L5,2,2)+2 -> E23 | N5: =MID(M5,1,1)&MID(M5,2,2)+2 -> E25 | O5: =MID(N5,1,1)&MID(N5,2,2)+2 -> E27 | P5: =MID(O5,1,1)&MID(O5,2,2)+2 -> E29 | ... V5: =MID(U5,1,1)&MID(U5,2,2)+2 -> E41 | W5: =MID(V5,1,1)&MID(V5,2,2)+1 -> E42 | X5: =MID(W5,1,1)&MID(W5,2,2)+1 -> E43 | Y5: =MID(X5,1,1)&MID(X5,2,2)+1 -> E44
H6: F13 | I6: =MID(H6,1,1)&MID(H6,2,2)+2 -> F15 | J6: =MID(I6,1,1)&MID(I6,2,2)+2 -> F17 | K6: =MID(J6,1,1)&MID(J6,2,2)+2 -> F19 | L6: =MID(K6,1,1)&MID(K6,2,2)+2 -> F21 | M6: =MID(L6,1,1)&MID(L6,2,2)+2 -> F23 | N6: =MID(M6,1,1)&MID(M6,2,2)+2 -> F25 | O6: =MID(N6,1,1)&MID(N6,2,2)+2 -> F27 | P6: =MID(O6,1,1)&MID(O6,2,2)+2 -> F29 | ... V6: =MID(U6,1,1)&MID(U6,2,2)+2 -> F41 | W6: =MID(V6,1,1)&MID(V6,2,2)+1 -> F42 | X6: =MID(W6,1,1)&MID(W6,2,2)+1 -> F43 | Y6: =MID(X6,1,1)&MID(X6,2,2)+1 -> F44
A7: Job Number | B7: ='Device Cables'!B1 -> 9628-003 | H7: Job Number: | J7: =B7 -> 9628-003
A8: Job Desc: | B8: ='Device Cables'!B2 -> GM ORN - ZJ040 - NFP 3 FRONT PIERCE - T1XXF1_2 | H8: Job Description: | J8: =B8 -> GM ORN - ZJ040 - NFP 3 FRONT PIERCE - T1XXF1_2
A10: Cabinet Labels | H10: =CONCATENATE(AB1," - ", M26, " ",AB2) -> PORT LAYOUT - RIGHT HAND SIDE OF ENCLOSURE
A11: Job # | B11: System | C11: Device | D11: Line 1 | E11: Line 2 | F11: Line 3
A12: =B7 -> 9628-003 | B12: =B8 -> GM ORN - ZJ040 - NFP 3 FRONT PIERCE - T1XXF1_2 | C12: CB05-1 | D12: ZJ040_R05 | E12: =IF(C12<>"",C12,"") -> CB05-1 | F12: POWER | H12: =IF(INDIRECT(H1)=0,"",INDIRECT(H1)) -> ZJ040_R05 | I12: =IF(INDIRECT(I1)=0,"",INDIRECT(I1)) -> ZJ040_R06 | J12: =IF(INDIRECT(J1)=0,"",INDIRECT(J1)) -> RH MET STAND | K12: =IF(INDIRECT(K1)=0,"",INDIRECT(K1)) -> LH INOS STAND | L12: =IF(INDIRECT(L1)=0,"",INDIRECT(L1)) -> RH INOS STAND | M12: =IF(INDIRECT(M1)=0,"",INDIRECT(M1)) -> SPARE #1 | N12: =IF(INDIRECT(N1)=0,"",INDIRECT(N1)) -> SPARE #2 | O12: =IF(INDIRECT(O1)=0,"",INDIRECT(O1)) -> SPARE #3 | P12: =IF(INDIRECT(P1)=0,"",INDIRECT(P1)) -> SPARE #4
D13: =D12 -> ZJ040_R05 | E13: =E12 -> CB05-1 | F13: ETHERNET | H13: =IF(INDIRECT(H2)=0,"",INDIRECT(H2)) -> CB05-1 | I13: =IF(INDIRECT(I2)=0,"",INDIRECT(I2)) -> CB06-1 | J13: =IF(INDIRECT(J2)=0,"",INDIRECT(J2)) -> CB-2 | K13: =IF(INDIRECT(K2)=0,"",INDIRECT(K2)) -> CB-3 | L13: =IF(INDIRECT(L2)=0,"",INDIRECT(L2)) -> CB-4 | M13: =IF(INDIRECT(M2)=0,"",INDIRECT(M2)) | N13: =IF(INDIRECT(N2)=0,"",INDIRECT(N2)) | O13: =IF(INDIRECT(O2)=0,"",INDIRECT(O2)) | P13: =IF(INDIRECT(P2)=0,"",INDIRECT(P2))
C14: CB06-1 | D14: ZJ040_R06 | E14: =IF(C14<>"",C14,"") -> CB06-1 | F14: POWER | H14: =IF(INDIRECT(H3)=0,"",INDIRECT(H3)) -> POWER | I14: =IF(INDIRECT(I3)=0,"",INDIRECT(I3)) -> POWER | J14: =IF(INDIRECT(J3)=0,"",INDIRECT(J3)) -> POWER | K14: =IF(INDIRECT(K3)=0,"",INDIRECT(K3)) -> POWER | L14: =IF(INDIRECT(L3)=0,"",INDIRECT(L3)) -> POWER | M14: =IF(INDIRECT(M3)=0,"",INDIRECT(M3)) -> POWER | N14: =IF(INDIRECT(N3)=0,"",INDIRECT(N3)) -> POWER | O14: =IF(INDIRECT(O3)=0,"",INDIRECT(O3)) -> POWER | P14: =IF(INDIRECT(P3)=0,"",INDIRECT(P3)) -> POWER
D15: =D14 -> ZJ040_R06 | E15: =E14 -> CB06-1 | F15: ETHERNET
C16: CB-2 | D16: RH MET STAND | E16: =IF(C16<>"",C16,"") -> CB-2 | F16: POWER
D17: =D16 -> RH MET STAND | E17: =E16 -> CB-2 | F17: ETHERNET
C18: CB-3 | D18: LH INOS STAND | E18: =IF(C18<>"",C18,"") -> CB-3 | F18: POWER | H18: =IF(INDIRECT(H4)=0,"",INDIRECT(H4)) -> ZJ040_R05 | I18: =IF(INDIRECT(I4)=0,"",INDIRECT(I4)) -> ZJ040_R06 | J18: =IF(INDIRECT(J4)=0,"",INDIRECT(J4)) -> RH MET STAND | K18: =IF(INDIRECT(K4)=0,"",INDIRECT(K4)) -> LH INOS STAND | L18: =IF(INDIRECT(L4)=0,"",INDIRECT(L4)) -> RH INOS STAND | M18: =IF(INDIRECT(M4)=0,"",INDIRECT(M4)) -> SPARE #1 | N18: =IF(INDIRECT(N4)=0,"",INDIRECT(N4)) -> SPARE #2 | O18: =IF(INDIRECT(O4)=0,"",INDIRECT(O4)) -> SPARE #3 | P18: =IF(INDIRECT(P4)=0,"",INDIRECT(P4)) -> SPARE #4
D19: =D18 -> LH INOS STAND | E19: =E18 -> CB-3 | F19: ETHERNET | H19: =IF(INDIRECT(H5)=0,"",INDIRECT(H5)) -> CB05-1 | I19: =IF(INDIRECT(I5)=0,"",INDIRECT(I5)) -> CB06-1 | J19: =IF(INDIRECT(J5)=0,"",INDIRECT(J5)) -> CB-2 | K19: =IF(INDIRECT(K5)=0,"",INDIRECT(K5)) -> CB-3 | L19: =IF(INDIRECT(L5)=0,"",INDIRECT(L5)) -> CB-4 | M19: =IF(INDIRECT(M5)=0,"",INDIRECT(M5)) | N19: =IF(INDIRECT(N5)=0,"",INDIRECT(N5)) | O19: =IF(INDIRECT(O5)=0,"",INDIRECT(O5)) | P19: =IF(INDIRECT(P5)=0,"",INDIRECT(P5))
C20: CB-4 | D20: RH INOS STAND | E20: =IF(C20<>"",C20,"") -> CB-4 | F20: POWER | H20: =IF(INDIRECT(H6)=0,"",INDIRECT(H6)) -> ETHERNET | I20: =IF(INDIRECT(I6)=0,"",INDIRECT(I6)) -> ETHERNET | J20: =IF(INDIRECT(J6)=0,"",INDIRECT(J6)) -> ETHERNET | K20: =IF(INDIRECT(K6)=0,"",INDIRECT(K6)) -> ETHERNET | L20: =IF(INDIRECT(L6)=0,"",INDIRECT(L6)) -> ETHERNET | M20: =IF(INDIRECT(M6)=0,"",INDIRECT(M6)) -> ETHERNET | N20: =IF(INDIRECT(N6)=0,"",INDIRECT(N6)) -> ETHERNET | O20: =IF(INDIRECT(O6)=0,"",INDIRECT(O6)) -> ETHERNET | P20: =IF(INDIRECT(P6)=0,"",INDIRECT(P6)) -> ETHERNET
D21: =D20 -> RH INOS STAND | E21: =E20 -> CB-4 | F21: ETHERNET
D22: SPARE #1 | E22: =IF(C22<>"",C22,"") | F22: POWER
D23: =D22 -> SPARE #1 | E23: =E22 | F23: ETHERNET
D24: SPARE #2 | E24: =IF(C24<>"",C24,"") | F24: POWER | H24: =IF(INDIRECT(Q1)=0,"",INDIRECT(Q1)) -> R05 REF STAND | I24: =IF(INDIRECT(R1)=0,"",INDIRECT(R1)) -> R06 REF STAND | J24: =IF(INDIRECT(S1)=0,"",INDIRECT(S1)) -> RM SPARE #1 | K24: =IF(INDIRECT(T1)=0,"",INDIRECT(T1)) -> RM SPARE #2 | L24: =IF(INDIRECT(U1)=0,"",INDIRECT(U1))
D25: =D24 -> SPARE #2 | E25: =E24 | F25: ETHERNET | H25: =IF(INDIRECT(Q2)=0,"",INDIRECT(Q2)) -> RM-1 | I25: =IF(INDIRECT(R2)=0,"",INDIRECT(R2)) -> RM-2 | J25: =IF(INDIRECT(S2)=0,"",INDIRECT(S2)) | K25: =IF(INDIRECT(T2)=0,"",INDIRECT(T2)) | L25: =IF(INDIRECT(U2)=0,"",INDIRECT(U2)) | M25: PORTS ON:
D26: SPARE #3 | E26: =IF(C26<>"",C26,"") | F26: POWER | H26: =IF(INDIRECT(Q3)=0,"",INDIRECT(Q3)) -> POWER | I26: =IF(INDIRECT(R3)=0,"",INDIRECT(R3)) -> POWER | J26: =IF(INDIRECT(S3)=0,"",INDIRECT(S3)) -> POWER | K26: =IF(INDIRECT(T3)=0,"",INDIRECT(T3)) -> POWER | L26: =IF(INDIRECT(U3)=0,"",INDIRECT(U3)) | M26: RIGHT HAND
D27: =D26 -> SPARE #3 | E27: =E26 | F27: ETHERNET | M27: SIDE OF ENCLOSURE
D28: SPARE #4 | E28: =IF(C28<>"",C28,"") | F28: POWER
D29: =D28 -> SPARE #4 | E29: =E28 | F29: ETHERNET
C30: RM-1 | D30: R05 REF STAND | E30: =IF(C30<>"",C30,"") -> RM-1 | F30: POWER | H30: =IF(INDIRECT(V1)=0,"",INDIRECT(V1)) -> EN1 - INOS | I30: =IF(INDIRECT(W1)=0,"",INDIRECT(W1)) -> EN2 - INOS | J30: =IF(INDIRECT(X1)=0,"",INDIRECT(X1)) -> EN3 - INOS | K30: =IF(INDIRECT(Y1)=0,"",INDIRECT(Y1)) -> EN4 - METRONOR | L30: =IF(INDIRECT(U4)=0,"",INDIRECT(U4))
H31: =IF(INDIRECT(V2)=0,"",INDIRECT(V2)) -> ETHERNET SM | I31: =IF(INDIRECT(W2)=0,"",INDIRECT(W2)) -> ETHERNET IP | J31: =IF(INDIRECT(X2)=0,"",INDIRECT(X2)) -> INOS DATA | K31: =IF(INDIRECT(Y2)=0,"",INDIRECT(Y2)) -> ETHERNET SM | L31: =IF(INDIRECT(U5)=0,"",INDIRECT(U5))
C32: RM-2 | D32: R06 REF STAND | E32: =IF(C32<>"",C32,"") -> RM-2 | F32: POWER | H32: =IF(INDIRECT(V3)=0,"",INDIRECT(V3)) -> TO CELL SWITCH | I32: =IF(INDIRECT(W3)=0,"",INDIRECT(W3)) -> TO CELL SWITCH | J32: =IF(INDIRECT(X3)=0,"",INDIRECT(X3)) -> PLANT NETWORK | K32: =IF(INDIRECT(Y3)=0,"",INDIRECT(Y3)) -> TO CELL SWITCH | L32: =IF(INDIRECT(U6)=0,"",INDIRECT(U6))
D34: RM SPARE #1 | E34: =IF(C34<>"",C34,"") | F34: POWER
D35: =IF(C34<>"",D34,"") | E35: =E34
D36: RM SPARE #2 | E36: =IF(C36<>"",C36,"") | F36: POWER
D37: =IF(C36<>"",D36,"") | E37: =E36
E38: =IF(C38<>"",C38,"")
D39: =IF(C38<>"",D38,"") | E39: =E38
C40: ENET TO CELL SWITCH | D40: EN1 - INOS | E40: ETHERNET SM | F40: TO CELL SWITCH
C41: EIP TO CELL SWITCH | D41: EN2 - INOS | E41: ETHERNET IP | F41: TO CELL SWITCH
C42: EIP TO CELL SWITCH | D42: EN3 - INOS | E42: INOS DATA | F42: PLANT NETWORK
...

Sheet PRNT ENC Labels
A1: Line 1 | B1: Line 2 | C1: Line 3 | D1: Qty
A2: =IF('ENC Labels'!D12<>"",'ENC Labels'!D12,"") -> ZJ040_R05 | B2: =IF(A2<>"",'ENC Labels'!E12,"") -> CB05-1 | C2: =IF(A2<>"",'ENC Labels'!F12,"") -> POWER | D2: =IF(A2<>"",1,"") -> 1
A3: =IF('ENC Labels'!D13<>"",'ENC Labels'!D13,"") -> ZJ040_R05 | B3: =IF(A3<>"",'ENC Labels'!E13,"") -> CB05-1 | C3: =IF(A3<>"",'ENC Labels'!F13,"") -> ETHERNET | D3: =IF(A3<>"",1,"") -> 1
A4: =IF('ENC Labels'!D14<>"",'ENC Labels'!D14,"") -> ZJ040_R06 | B4: =IF(A4<>"",'ENC Labels'!E14,"") -> CB06-1 | C4: =IF(A4<>"",'ENC Labels'!F14,"") -> POWER | D4: =IF(A4<>"",1,"") -> 1
A5: =IF('ENC Labels'!D15<>"",'ENC Labels'!D15,"") -> ZJ040_R06 | B5: =IF(A5<>"",'ENC Labels'!E15,"") -> CB06-1 | C5: =IF(A5<>"",'ENC Labels'!F15,"") -> ETHERNET | D5: =IF(A5<>"",1,"") -> 1
A6: =IF('ENC Labels'!D16<>"",'ENC Labels'!D16,"") -> RH MET STAND | B6: =IF(A6<>"",'ENC Labels'!E16,"") -> CB-2 | C6: =IF(A6<>"",'ENC Labels'!F16,"") -> POWER | D6: =IF(A6<>"",1,"") -> 1
A7: =IF('ENC Labels'!D17<>"",'ENC Labels'!D17,"") -> RH MET STAND | B7: =IF(A7<>"",'ENC Labels'!E17,"") -> CB-2 | C7: =IF(A7<>"",'ENC Labels'!F17,"") -> ETHERNET | D7: =IF(A7<>"",1,"") -> 1
A8: =IF('ENC Labels'!D18<>"",'ENC Labels'!D18,"") -> LH INOS STAND | B8: =IF(A8<>"",'ENC Labels'!E18,"") -> CB-3 | C8: =IF(A8<>"",'ENC Labels'!F18,"") -> POWER | D8: =IF(A8<>"",1,"") -> 1
A9: =IF('ENC Labels'!D19<>"",'ENC Labels'!D19,"") -> LH INOS STAND | B9: =IF(A9<>"",'ENC Labels'!E19,"") -> CB-3 | C9: =IF(A9<>"",'ENC Labels'!F19,"") -> ETHERNET | D9: =IF(A9<>"",1,"") -> 1
A10: =IF('ENC Labels'!D20<>"",'ENC Labels'!D20,"") -> RH INOS STAND | B10: =IF(A10<>"",'ENC Labels'!E20,"") -> CB-4 | C10: =IF(A10<>"",'ENC Labels'!F20,"") -> POWER | D10: =IF(A10<>"",1,"") -> 1
A11: =IF('ENC Labels'!D21<>"",'ENC Labels'!D21,"") -> RH INOS STAND | B11: =IF(A11<>"",'ENC Labels'!E21,"") -> CB-4 | C11: =IF(A11<>"",'ENC Labels'!F21,"") -> ETHERNET | D11: =IF(A11<>"",1,"") -> 1
A12: =IF('ENC Labels'!D22<>"",'ENC Labels'!D22,"") -> SPARE #1 | B12: =IF(A12<>"",'ENC Labels'!E22,"") | C12: =IF(A12<>"",'ENC Labels'!F22,"") -> POWER | D12: =IF(A12<>"",1,"") -> 1
A13: =IF('ENC Labels'!D23<>"",'ENC Labels'!D23,"") -> SPARE #1 | B13: =IF(A13<>"",'ENC Labels'!E23,"") | C13: =IF(A13<>"",'ENC Labels'!F23,"") -> ETHERNET | D13: =IF(A13<>"",1,"") -> 1
... A20: =IF('ENC Labels'!D30<>"",'ENC Labels'!D30,"") -> R05 REF STAND | B20: =IF(A20<>"",'ENC Labels'!E30,"") -> RM-1 | C20: =IF(A20<>"",'ENC Labels'!F30,"") -> POWER | D20: =IF(A20<>"",1,"") -> 1
A21: =IF('ENC Labels'!D32<>"",'ENC Labels'!D32,"") -> R06 REF STAND | B21: =IF(A21<>"",'ENC Labels'!E32,"") -> RM-2 | C21: =IF(A21<>"",'ENC Labels'!F32,"") -> POWER | D21: =IF(A21<>"",1,"") -> 1
A22: =IF('ENC Labels'!D34<>"",'ENC Labels'!D34,"") -> RM SPARE #1 | B22: =IF(A22<>"",'ENC Labels'!E34,"") | C22: =IF(A22<>"",'ENC Labels'!F34,"") -> POWER | D22: =IF(A22<>"",1,"") -> 1
A23: =IF('ENC Labels'!D36<>"",'ENC Labels'!D36,"") -> RM SPARE #2 | B23: =IF(A23<>"",'ENC Labels'!E36,"") | C23: =IF(A23<>"",'ENC Labels'!F36,"") -> POWER | D23: =IF(A23<>"",1,"") -> 1
A24: =IF('ENC Labels'!D40<>"",'ENC Labels'!D40,"") -> EN1 - INOS | B24: =IF(A24<>"",'ENC Labels'!E40,"") -> ETHERNET SM | C24: =IF(A24<>"",'ENC Labels'!F40,"") -> TO CELL SWITCH | D24: =IF(A24<>"",1,"") -> 1
A25: =IF('ENC Labels'!D41<>"",'ENC Labels'!D41,"") -> EN2 - INOS | B25: =IF(A25<>"",'ENC Labels'!E41,"") -> ETHERNET IP | C25: =IF(A25<>"",'ENC Labels'!F41,"") -> TO CELL SWITCH | D25: =IF(A25<>"",1,"") -> 1
A26: =IF('ENC Labels'!D42<>"",'ENC Labels'!D42,"") -> EN3 - INOS | B26: =IF(A26<>"",'ENC Labels'!E42,"") -> INOS DATA | C26: =IF(A26<>"",'ENC Labels'!F42,"") -> PLANT NETWORK | D26: =IF(A26<>"",1,"") -> 1
A27: =IF('ENC Labels'!D43<>"",'ENC Labels'!D43,"") -> EN4 - METRONOR | B27: =IF(A27<>"",'ENC Labels'!E43,"") -> ETHERNET SM | C27: =IF(A27<>"",'ENC Labels'!F43,"") -> TO CELL SWITCH | D27: =IF(A27<>"",1,"") -> 1
A28: =IF('ENC Labels'!D44<>"",'ENC Labels'!D44,"") | B28: =IF(A28<>"",'ENC Labels'!E44,"") | C28: =IF(A28<>"",'ENC Labels'!F44,"") | D28: =IF(A28<>"",1,"")
A29: =IF('ENC Labels'!D45<>"",'ENC Labels'!D45,"") | B29: =IF(A29<>"",'ENC Labels'!E45,"") | C29: =IF(A29<>"",'ENC Labels'!F45,"") | D29: =IF(A29<>"",1,"")
A30: =IF('ENC Labels'!D46<>"",'ENC Labels'!D46,"") | B30: =IF(A30<>"",'ENC Labels'!E46,"") | C30: =IF(A30<>"",'ENC Labels'!F46,"") | D30: =IF(A30<>"",1,"")
A31: =IF('ENC Labels'!D47<>"",'ENC Labels'!D47,"") | B31: =IF(A31<>"",'ENC Labels'!E47,"") | C31: =IF(A31<>"",'ENC Labels'!F47,"") | D31: =IF(A31<>"",1,"")
A32: =IF('ENC Labels'!D48<>"",'ENC Labels'!D48,"") | B32: =IF(A32<>"",'ENC Labels'!E48,"") | C32: =IF(A32<>"",'ENC Labels'!F48,"") | D32: =IF(A32<>"",1,"")
A33: =IF('ENC Labels'!D49<>"",'ENC Labels'!D49,"") | B33: =IF(A33<>"",'ENC Labels'!E49,"") | C33: =IF(A33<>"",'ENC Labels'!F49,"") | D33: =IF(A33<>"",1,"")
A34: =IF('ENC Labels'!D50<>"",'ENC Labels'!D50,"") | B34: =IF(A34<>"",'ENC Labels'!E50,"") | C34: =IF(A34<>"",'ENC Labels'!F50,"") | D34: =IF(A34<>"",1,"")
A35: =IF('ENC Labels'!D51<>"",'ENC Labels'!D51,"") | B35: =IF(A35<>"",'ENC Labels'!E51,"") | C35: =IF(A35<>"",'ENC Labels'!F51,"") | D35: =IF(A35<>"",1,"")
... A160: =IF('ENC Labels'!D176<>"",'ENC Labels'!D176,"") | B160: =IF(A160<>"",'ENC Labels'!E176,"") | C160: =IF(A160<>"",'ENC Labels'!F176,"") | D160: =IF(A160<>"",1,"")

Sheet Stand labels
B10: Customer Plant: | C10: GM ORN
B11: Job - Station - Function: | C11: ZJ040 - NFP 3 - FRONT PIERCE
B12: SIDE - Floor Stand | C12: LHFLR-V STAND
B26: Customer Plant: | C26: GM ORN
B27: Job - Station - Function: | C27: ZJ040 - NFP 3 - FRONT PIERCE
B28: SIDE - Floor Stand | C28: RHFLR-V STAND
B42: Customer Plant: | C42: GM ORN
B43: Job - Station - Function: | C43: ZJ040 - NFP 3 - FRONT PIERCE
B44: SIDE - Floor Stand | C44: REFRENCE STAND
B58: Customer Plant: | C58: GM ORN
B59: Job - Station - Function: | C59: ZJ040 - NFP 3 - FRONT PIERCE
B60: SIDE - Floor Stand | C60: REFRENCE STAND
B74: Customer Plant:
B75: Job - Station - Function:
B76: SIDE - Floor Stand
B90: Customer Plant:
B91: Job - Station - Function:
B92: SIDE - Floor Stand
B106: Customer Plant:
B107: Job - Station - Function:
B108: SIDE - Floor Stand
B122: Customer Plant:
B123: Job - Station - Function:
B124: SIDE - Floor Stand
... B156: SIDE - Floor Stand

Sheet PRNT Stand labels
A1: LINE 1 | B1: LINE 2 | C1: LINE 3 | D1: QTY
A2: =IF('Stand labels'!C10=0," ",'Stand labels'!C10) -> GM ORN | B2: =IF('Stand labels'!C11=0," ",'Stand labels'!C11) -> ZJ040 - NFP 3 - FRONT PIERCE | C2: =IF('Stand labels'!C12=0," ",'Stand labels'!C12) -> LHFLR-V STAND | D2: =IF(A2<>" ",3,IF(B2<>" ",2,IF(C2<>" ",2," "))) -> 3
